Workbook
Name LIST_TEC_NGUON: DANH_MUC!$A$4:$A$14
Name LIST_KY_TINH: TINH_TEC!$A$6:$A$155

Sheet HUONG_DAN
A1: HƯỚNG DẪN SỬ DỤNG
A2: Đọc trước khi sử dụng — Mật khẩu sheet khóa: 1111
A3: Nhóm sheet | B3: Cách sử dụng | D3: Mật khẩu sheet khóa | E3: 1111
A4: Sheet | B4: Ai dùng chính | C4: Mục đích | D4: Có được sửa trực tiếp? | E4: Chú thích | H4: Ô được phép nhập liệu
A5: BOM | B5: Thủ kho | C5: Nhập dữ liệu bơm/xuất dầu cho xe: số phiếu, biển số, téc/nguồn, loại giao dịch, số lít, KM cũ/mới. | D5: Có
A6: NHAP | B6: Thủ kho/Kế toán kho | C6: Nhập dữ liệu mỗi lần công ty mua/nhập dầu về téc: NCC, téc nhận dầu, loại dầu, số lít, đơn giá. | D6: Có
A7: TON_KHO | B7: Thủ kho/Kế toán kho | C7: Xem tồn kho theo ngày. Logic: Tồn = Tồn đầu + Nhập - Xuất - Tịnh âm + Tịnh dương. | D7: Chỉ nhập/cập nhật Tồn đầu theo số đo thực tế; không sửa công thức nhập/xuất/tịnh/tồn sau tịnh.
A8: TONG_HOP_XE | B8: Kế toán | C8: Xem tiêu hao từng xe theo tháng theo layout quen thuộc: ngày 1-31, tổng, bơm ngoài, tịnh âm/dương, tổng tiêu hao, KM, L/100km. | D8: Chỉ chỉnh Tháng/Năm. Tịnh và KM/L100km đã tự kéo từ TINH_TEC/DATA_GOC; không nhập tay.
A9: EXPORT_KE_TOAN | B9: Kế toán | C9: Trích xuất dữ liệu BOM/NHAP theo tháng để copy gửi kế toán. Chỉnh B3 = tháng, D3 = năm; dữ liệu tự cập nhật. | D9: Chỉ chỉnh B3/D3.
A10: DATA_GOC | B10: Quản trị file | C10: Database gốc lưu toàn bộ dữ liệu mọi thời điểm. Các sheet khác đều đọc từ đây. | D10: Không sửa trực tiếp; đang khóa mật khẩu 1111.
A11: DANH_MUC | B11: Quản trị file | C11: Danh sách: téc/nguồn, loại dầu, loại giao dịch, nhà cung cấp, biển số/thiết bị. | D11: Cập nhật khi phát sinh xe/NCC mới. Các sheet phân bổ/tổng hợp đọc từ danh mục này.
A12: TINH_TEC | B12: Kế toán | C12: Nhập kỳ tịnh khi thủ kho báo téc hết: chọn téc, ngày bắt đầu, ngày hết, tồn đầu kỳ/thực tế. Sheet tự tính tịnh âm/dương và phân bổ cho từng xe. | D12: Sửa các ô nhập liệu màu xám; không sửa công thức.
A64: Bổ sung: Quy trình TINH_TEC | B64: Khi téc hết nhẵn, kế toán vào TINH_TEC, nhập kỳ tịnh ở bảng trên, chọn KyTinhID để kiểm tra dashboard, sau đó đổi trạng thái sang Đã chốt để số tịnh tự cộng sang TONG_HOP_TEC và TON_KHO.

Sheet CAI_DAT_EMAIL
A1: Cấu hình email báo cáo tồn kho
A2: Danh sách email nhận | B2: ahuyle.work@gmail.com, nguyenkhanh.tsm@gmail.com, thuannv.thiennhat@gmail.com
A3: Giờ gửi mỗi ngày | B3: 17
A4: Ghi chú | B4: Có thể nhập nhiều email, cách nhau bằng dấu phẩy hoặc chấm phẩy.
A5: Function test | B5: guiThuEmailTonKhoCuoiNgay

Sheet LOG_NHAP_LIEU
A1: Timestamp | B1: User | C1: Status | D1: LoaiDuLieu | E1: DATA_GOC_Row | F1: Ngay | G1: SoPhieu | H1: DoiTuong/NCC | I1: Tec_Nguon | J1: LoaiGiaoDich | K1: LoaiDau | L1: SoLit | M1: KMCu | N1: KMMoi | O1: KMDi | P1: DonGia | Q1: ThanhTien | R1: GhiChu | S1: Message
A2: 46185.701 | B2: vriens.gpt@gmail.com | C2: SAVE_OK | D2: BOM: 1 dòng, DATA_GOC từ dòng 1439
A3: 46185.702 | B3: vriens.gpt@gmail.com | C3: SAVE_OK | D3: BOM: 1 dòng, DATA_GOC từ dòng 1440
A4: 46185.703 | B4: vriens.gpt@gmail.com | C4: SAVE_OK | D4: BOM: 1 dòng, DATA_GOC từ dòng 1441
A5: 46185.703 | B5: vriens.gpt@gmail.com | C5: SAVE_OK | D5: NHAP: 1 dòng, DATA_GOC từ dòng 1442
A6: 46186.349 | B6: lekhamuoi@gmail.com | C6: SAVE_ERROR | D6: BOM: Bạn đang cố gắng chỉnh sửa ô hoặc đối tượng được bảo vệ. Vui lòng liên hệ với chủ sở hữu bảng tính để tắt chế độ bảo vệ nếu bạn cần chỉnh sửa.
A7: 46186.349 | B7: lekhamuoi@gmail.com | C7: SAVE_ERROR | D7: BOM: Bạn đang cố gắng chỉnh sửa ô hoặc đối tượng được bảo vệ. Vui lòng liên hệ với chủ sở hữu bảng tính để tắt chế độ bảo vệ nếu bạn cần chỉnh sửa.
A8: 46188.903 | B8: vriens.gpt@gmail.com | C8: SAVE_OK | D8: BOM | E8: 1481 | F8: 46188 | H8: 19H09482 | I8: Téc 1 | J8: Xuất nội bộ từ téc | K8: DO 0.05S | L8: 1 | S8: BOM: đã lưu 1 dòng vào DATA_GOC
A9: 46188.903 | B9: vriens.gpt@gmail.com | C9: SAVE_OK | D9: BOM | E9: 1482 | F9: 46188 | H9: 19H09482 | I9: Téc 1 | J9: Xuất nội bộ từ téc | K9: DO 0.05S | L9: 1 | S9: BOM: đã lưu 1 dòng vào DATA_GOC
A10: 46189.406 | B10: lekhamuoi@gmail.com | C10: SAVE_OK | D10: BOM | E10: 1481 | F10: 46188 | H10: 28C02986 | I10: Téc 3 | J10: Xuất nội bộ từ téc | K10: DO 0.05S | L10: 415 | M10: 95589 | N10: 96491 | O10: 902 | S10: BOM: đã lưu 1 dòng vào DATA_GOC
A11: 46189.406 | B11: lekhamuoi@gmail.com | C11: SAVE_OK | D11: BOM | E11: 1482 | F11: 46188 | H11: 19H09482 | I11: Téc 3 | J11: Xuất nội bộ từ téc | K11: DO 0.05S | L11: 460 | M11: 23404 | N11: 24367 | O11: 963 | S11: BOM: đã lưu 1 dòng vào DATA_GOC
A12: 46189.406 | B12: lekhamuoi@gmail.com | C12: SAVE_OK | D12: BOM | E12: 1483 | F12: 46188 | H12: 28C00462 | I12: Téc 3 | J12: Xuất nội bộ từ téc | K12: DO 0.05S | L12: 36 | R12: bơm máy lai | S12: BOM: đã lưu 1 dòng vào DATA_GOC
A13: 46189.672 | B13: lekhamuoi@gmail.com | C13: SAVE_OK | D13: BOM | E13: 1484 | F13: 46189 | H13: 28C05739 | I13: Téc 3 | J13: Xuất nội bộ từ téc | K13: DO 0.05S | L13: 238 | M13: 191346 | N13: 191860 | O13: 514 | S13: BOM: đã lưu 1 dòng vào DATA_GOC
A14: 46189.672 | B14: lekhamuoi@gmail.com | C14: SAVE_OK | D14: BOM | E14: 1485 | F14: 46189 | H14: 28C03652 | I14: Téc 3 | J14: Xuất nội bộ từ téc | K14: DO 0.05S | L14: 244 | M14: 264541 | N14: 265070 | O14: 529 | S14: BOM: đã lưu 1 dòng vào DATA_GOC
A15: 46189.672 | B15: lekhamuoi@gmail.com | C15: SAVE_OK | D15: BOM | E15: 1486 | F15: 46189 | H15: 28H00680 | I15: Téc 3 | J15: Xuất nội bộ từ téc | K15: DO 0.05S | L15: 477 | M15: 243778 | N15: 244724 | O15: 946 | S15: BOM: đã lưu 1 dòng vào DATA_GOC
A16: 46189.672 | B16: lekhamuoi@gmail.com | C16: SAVE_OK | D16: BOM | E16: 1487 | F16: 46189 | H16: 28C02770 | I16: Téc 3 | J16: Xuất nội bộ từ téc | K16: DO 0.05S | L16: 512 | M16: 7401 | N16: 8378 | O16: 977 | S16: BOM: đã lưu 1 dòng vào DATA_GOC
A17: 46189.815 | B17: vriens.gpt@gmail.com | C17: SAVE_ERROR | S17: BOM: BOM dòng 6: thiếu téc/nguồn.
A18: 46189.815 | B18: vriens.gpt@gmail.com | C18: SAVE_OK | D18: BOM | E18: 1488 | F18: 46189 | H18: 28A30696 | I18: Téc 1 | J18: Xuất nội bộ từ téc | K18: DO 0.05S | L18: 200 | M18: 11 | N18: 12 | O18: 1 | S18: BOM: đã lưu 1 dòng vào DATA_GOC
A19: 46190.247 | B19: lekhamuoi@gmail.com | C19: SAVE_OK | D19: BOM | E19: 1488 | F19: 46189 | H19: 28C03385 | I19: Dầu thủy lực | J19: Xuất nội bộ từ téc | K19: Dầu thủy lực | L19: 3 | R19: Bổ sung bót lái | S19: BOM: đã lưu 1 dòng vào DATA_GOC
A20: 46190.247 | B20: lekhamuoi@gmail.com | C20: SAVE_OK | D20: BOM | E20: 1489 | F20: 46189 | H20: 28C03385 | I20: Téc 3 | J20: Xuất nội bộ từ téc | K20: DO 0.05S | L20: 30 | R20: Bơm tạm đủ chạy đi sửa xe | S20: BOM: đã lưu 1 dòng vào DATA_GOC
A21: 46190.247 | B21: lekhamuoi@gmail.com | C21: SAVE_OK | D21: BOM | E21: 1490 | F21: 46189 | H21: 28H00003 | I21: Téc 3 | J21: Xuất nội bộ từ téc | K21: DO 0.05S | L21: 370 | M21: 79455 | N21: 80207 | O21: 752 | S21: BOM: đã lưu 1 dòng vào DATA_GOC
A22: 46190.247 | B22: lekhamuoi@gmail.com | C22: SAVE_OK | D22: BOM | E22: 1491 | F22: 46189 | H22: 28C05345 | I22: Téc 3 | J22: Xuất nội bộ từ téc | K22: DO 0.05S | L22: 306 | M22: 182478 | N22: 182743 | O22: 265 | S22: BOM: đã lưu 1 dòng vào DATA_GOC
A23: 46190.247 | B23: lekhamuoi@gmail.com | C23: SAVE_OK | D23: BOM | E23: 1492 | F23: 46189 | H23: 28H00061 | I23: Téc 3 | J23: Xuất nội bộ từ téc | K23: DO 0.05S | L23: 164 | M23: 167544 | N23: 167916 | O23: 372 | S23: BOM: đã lưu 1 dòng vào DATA_GOC
A24: 46190.247 | B24: lekhamuoi@gmail.com | C24: SAVE_OK | D24: BOM | E24: 1493 | F24: 46189 | H24: 28C01622 | I24: Téc 3 | J24: Xuất nội bộ từ téc | K24: DO 0.05S | L24: 350 | M24: 153251 | N24: 153934 | O24: 683 | S24: BOM: đã lưu 1 dòng vào DATA_GOC
A25: 46190.247 | B25: lekhamuoi@gmail.com | C25: SAVE_OK | D25: BOM | E25: 1494 | F25: 46189 | H25: 28C06447 | I25: Téc 3 | J25: Xuất nội bộ từ téc | K25: DO 0.05S | L25: 315 | M25: 407553 | N25: 408237 | O25: 684 | S25: BOM: đã lưu 1 dòng vào DATA_GOC
A26: 46190.724 | B26: lekhamuoi@gmail.com | C26: SAVE_OK | D26: BOM | E26: 1495 | F26: 46190 | H26: 28H00603 | I26: Téc 3 | J26: Xuất nội bộ từ téc | K26: DO 0.05S | L26: 239 | M26: 116959 | N26: 117559 | O26: 600 | S26: BOM: đã lưu 1 dòng vào DATA_GOC
A27: 46190.724 | B27: lekhamuoi@gmail.com | C27: SAVE_OK | D27: BOM | E27: 1496 | F27: 46190 | H27: 28C04576 | I27: Téc 3 | J27: Xuất nội bộ từ téc | K27: DO 0.05S | L27: 235 | N27: 254856 | S27: BOM: đã lưu 1 dòng vào DATA_GOC
A28: 46190.724 | B28: lekhamuoi@gmail.com | C28: SAVE_OK | D28: BOM | E28: 1497 | F28: 46190 | H28: Xúclật855H | I28: Téc 3 | J28: Xuất nội bộ từ téc | K28: DO 0.05S | L28: 158 | M28: 4312 | N28: 4326 | O28: 14 | S28: BOM: đã lưu 1 dòng vào DATA_GOC
A29: 46190.724 | B29: lekhamuoi@gmail.com | C29: SAVE_OK | D29: BOM | E29: 1498 | F29: 46190 | H29: 29E17410 | I29: Téc 3 | J29: Xuất nội bộ từ téc | K29: DO 0.05S | L29: 309 | M29: 5305 | N29: 5936 | O29: 631 | S29: BOM: đã lưu 1 dòng vào DATA_GOC
A30: 46190.724 | B30: lekhamuoi@gmail.com | C30: SAVE_OK | D30: BOM | E30: 1499 | F30: 46190 | H30: 28C02973 | I30: Téc 3 | J30: Xuất nội bộ từ téc | K30: DO 0.05S | L30: 230 | M30: 1447 | N30: 2052 | O30: 605 | S30: BOM: đã lưu 1 dòng vào DATA_GOC
A31: 46190.724 | B31: lekhamuoi@gmail.com | C31: SAVE_OK | D31: BOM | E31: 1500 | F31: 46190 | H31: 19H09482 | I31: Téc 3 | J31: Xuất nội bộ từ téc | K31: DO 0.05S | L31: 30 | R31: bơm máy lai | S31: BOM: đã lưu 1 dòng vào DATA_GOC
A32: 46190.724 | B32: lekhamuoi@gmail.com | C32: SAVE_OK | D32: BOM | E32: 1501 | F32: 46190 | H32: Cát nghiền | I32: Dầu cầu | J32: Xuất nội bộ từ téc | K32: Dầu cầu | L32: 20 | R32: bổ sung máy nghiền | S32: BOM: đã lưu 1 dòng vào DATA_GOC
A33: 46191.689 | B33: lekhamuoi@gmail.com | C33: SAVE_OK | D33: BOM | E33: 1502 | F33: 46191 | H33: Máy lu lốp | I33: Dầu động cơ | J33: Xuất nội bộ từ téc | K33: Dầu động cơ | L33: 40 | S33: BOM: đã lưu 1 dòng vào DATA_GOC
A34: 46191.689 | B34: lekhamuoi@gmail.com | C34: SAVE_OK | D34: BOM | E34: 1503 | F34: 46191 | H34: Máy rải thảm | I34: Dầu thủy lực | J34: Xuất nội bộ từ téc | K34: Dầu thủy lực | L34: 60 | S34: BOM: đã lưu 1 dòng vào DATA_GOC
A35: 46191.689 | B35: lekhamuoi@gmail.com | C35: SAVE_OK | D35: BOM | E35: 1504 | F35: 46191 | H35: 28C05345 | I35: Dầu thủy lực | J35: Xuất nội bộ từ téc | K35: Dầu thủy lực | L35: 176 | S35: BOM: đã lưu 1 dòng vào DATA_GOC
A36: 46191.689 | B36: lekhamuoi@gmail.com | C36: SAVE_OK | D36: BOM | E36: 1505 | F36: 46191 | H36: 28H00354 | I36: Téc 3 | J36: Xuất nội bộ từ téc | K36: DO 0.05S | L36: 257 | M36: 99407 | N36: 100007 | O36: 600 | S36: BOM: đã lưu 1 dòng vào DATA_GOC
A37: 46191.689 | B37: lekhamuoi@gmail.com | C37: SAVE_OK | D37: BOM | E37: 1506 | F37: 46191 | H37: 28C06369 | I37: Téc 3 | J37: Xuất nội bộ từ téc | K37: DO 0.05S | L37: 230 | M37: 172660 | N37: 173173 | O37: 513 | S37: BOM: đã lưu 1 dòng vào DATA_GOC
A38: 46191.689 | B38: lekhamuoi@gmail.com | C38: SAVE_OK | D38: BOM | E38: 1507 | F38: 46191 | H38: 28C03261 | I38: Téc 3 | J38: Xuất nội bộ từ téc | K38: DO 0.05S | L38: 260 | M38: 276347 | N38: 276819 | O38: 472 | S38: BOM: đã lưu 1 dòng vào DATA_GOC
A39: 46191.689 | B39: lekhamuoi@gmail.com | C39: SAVE_OK | D39: BOM | E39: 1508 | F39: 46191 | H39: 28C01406 | I39: Téc 3 | J39: Xuất nội bộ từ téc | K39: DO 0.05S | L39: 460 | M39: 15973 | N39: 17185 | O39: 1212 | S39: BOM: đã lưu 1 dòng vào DATA_GOC
A40: 46191.689 | B40: lekhamuoi@gmail.com | C40: SAVE_OK | D40: BOM | E40: 1509 | F40: 46191 | H40: 28H01070 | I40: Téc 3 | J40: Xuất nội bộ từ téc | K40: DO 0.05S | L40: 305 | M40: 80579 | N40: 81275 | O40: 696 | S40: BOM: đã lưu 1 dòng vào DATA_GOC
...

Sheet BOM
A1: BOM — Nhập liệu bơm dầu
A3: Ngày | B3: 46209 | C3: ① Điền thông tin bên dưới | D3: → Điền xong nhấn chọn Lưu Bơm
A5: # | B5: Số phiếu | C5: Biển số / Phương tiện | D5: Téc / Nguồn | E5: Loại giao dịch | F5: Loại dầu | G5: Số lít | H5: KM cũ | I5: KM mới | J5: KM đi | K5: Ghi chú | L5: KM mới lần bơm gần nhất
J6: =IF(OR(H6="",I6=""),"",MAX(0,I6-H6)) | L6: =IFERROR(__xludf.DUMMYFUNCTION("IF($C6="""","""",IFERROR(INDEX(SORT(FILTER({DATA_GOC!$B$4:$B$49999,DATA_GOC!$P$4:$P$49999,DATA_GOC!$J$4:$J$49999},DATA_GOC!$A$4:$A$49999=""BOM"",TRIM(DATA_GOC!$D$4:$D$49999)=TRIM($C6),DATA_GOC!$J$4:$J$49999<>"""",DATA_GOC!$B$4:$B$49999<=$B$3),1,FALSE,2,FA"&"LSE),1,3),""Chưa có dữ liệu""))"),"")
J7: =IF(OR(H7="",I7=""),"",MAX(0,I7-H7)) | L7: =IFERROR(__xludf.DUMMYFUNCTION("IF($C7="""","""",IFERROR(INDEX(SORT(FILTER({DATA_GOC!$B$4:$B$49999,DATA_GOC!$P$4:$P$49999,DATA_GOC!$J$4:$J$49999},DATA_GOC!$A$4:$A$49999=""BOM"",TRIM(DATA_GOC!$D$4:$D$49999)=TRIM($C7),DATA_GOC!$J$4:$J$49999<>"""",DATA_GOC!$B$4:$B$49999<=$B$3),1,FALSE,2,FA"&"LSE),1,3),""Chưa có dữ liệu""))"),"")
A8: =IF(C8="","",ROW()-5) | J8: =IF(OR(H8="",I8=""),"",MAX(0,I8-H8)) | L8: =IFERROR(__xludf.DUMMYFUNCTION("IF($C8="""","""",IFERROR(INDEX(SORT(FILTER({DATA_GOC!$B$4:$B$49999,DATA_GOC!$P$4:$P$49999,DATA_GOC!$J$4:$J$49999},DATA_GOC!$A$4:$A$49999=""BOM"",TRIM(DATA_GOC!$D$4:$D$49999)=TRIM($C8),DATA_GOC!$J$4:$J$49999<>"""",DATA_GOC!$B$4:$B$49999<=$B$3),1,FALSE,2,FA"&"LSE),1,3),""Chưa có dữ liệu""))"),"")
A9: =IF(C9="","",ROW()-5) | J9: =IF(OR(H9="",I9=""),"",MAX(0,I9-H9)) | L9: =IFERROR(__xludf.DUMMYFUNCTION("IF($C9="""","""",IFERROR(INDEX(SORT(FILTER({DATA_GOC!$B$4:$B$49999,DATA_GOC!$P$4:$P$49999,DATA_GOC!$J$4:$J$49999},DATA_GOC!$A$4:$A$49999=""BOM"",TRIM(DATA_GOC!$D$4:$D$49999)=TRIM($C9),DATA_GOC!$J$4:$J$49999<>"""",DATA_GOC!$B$4:$B$49999<=$B$3),1,FALSE,2,FA"&"LSE),1,3),""Chưa có dữ liệu""))"),"")
A10: =IF(C10="","",ROW()-5) | J10: =IF(OR(H10="",I10=""),"",MAX(0,I10-H10)) | L10: =IFERROR(__xludf.DUMMYFUNCTION("IF($C10="""","""",IFERROR(INDEX(SORT(FILTER({DATA_GOC!$B$4:$B$49999,DATA_GOC!$P$4:$P$49999,DATA_GOC!$J$4:$J$49999},DATA_GOC!$A$4:$A$49999=""BOM"",TRIM(DATA_GOC!$D$4:$D$49999)=TRIM($C10),DATA_GOC!$J$4:$J$49999<>"""",DATA_GOC!$B$4:$B$49999<=$B$3),1,FALSE,2,"&"FALSE),1,3),""Chưa có dữ liệu""))"),"")
A11: =IF(C11="","",ROW()-5) | J11: =IF(OR(H11="",I11=""),"",MAX(0,I11-H11)) | L11: =IFERROR(__xludf.DUMMYFUNCTION("IF($C11="""","""",IFERROR(INDEX(SORT(FILTER({DATA_GOC!$B$4:$B$49999,DATA_GOC!$P$4:$P$49999,DATA_GOC!$J$4:$J$49999},DATA_GOC!$A$4:$A$49999=""BOM"",TRIM(DATA_GOC!$D$4:$D$49999)=TRIM($C11),DATA_GOC!$J$4:$J$49999<>"""",DATA_GOC!$B$4:$B$49999<=$B$3),1,FALSE,2,"&"FALSE),1,3),""Chưa có dữ liệu""))"),"")
A12: =IF(C12="","",ROW()-5) | J12: =IF(OR(H12="",I12=""),"",MAX(0,I12-H12)) | L12: =IFERROR(__xludf.DUMMYFUNCTION("IF($C12="""","""",IFERROR(INDEX(SORT(FILTER({DATA_GOC!$B$4:$B$49999,DATA_GOC!$P$4:$P$49999,DATA_GOC!$J$4:$J$49999},DATA_GOC!$A$4:$A$49999=""BOM"",TRIM(DATA_GOC!$D$4:$D$49999)=TRIM($C12),DATA_GOC!$J$4:$J$49999<>"""",DATA_GOC!$B$4:$B$49999<=$B$3),1,FALSE,2,"&"FALSE),1,3),""Chưa có dữ liệu""))"),"")
A13: =IF(C13="","",ROW()-5) | J13: =IF(OR(H13="",I13=""),"",MAX(0,I13-H13)) | L13: =IFERROR(__xludf.DUMMYFUNCTION("IF($C13="""","""",IFERROR(INDEX(SORT(FILTER({DATA_GOC!$B$4:$B$49999,DATA_GOC!$P$4:$P$49999,DATA_GOC!$J$4:$J$49999},DATA_GOC!$A$4:$A$49999=""BOM"",TRIM(DATA_GOC!$D$4:$D$49999)=TRIM($C13),DATA_GOC!$J$4:$J$49999<>"""",DATA_GOC!$B$4:$B$49999<=$B$3),1,FALSE,2,"&"FALSE),1,3),""Chưa có dữ liệu""))"),"")
A14: =IF(C14="","",ROW()-5) | J14: =IF(OR(H14="",I14=""),"",MAX(0,I14-H14)) | L14: =IFERROR(__xludf.DUMMYFUNCTION("IF($C14="""","""",IFERROR(INDEX(SORT(FILTER({DATA_GOC!$B$4:$B$49999,DATA_GOC!$P$4:$P$49999,DATA_GOC!$J$4:$J$49999},DATA_GOC!$A$4:$A$49999=""BOM"",TRIM(DATA_GOC!$D$4:$D$49999)=TRIM($C14),DATA_GOC!$J$4:$J$49999<>"""",DATA_GOC!$B$4:$B$49999<=$B$3),1,FALSE,2,"&"FALSE),1,3),""Chưa có dữ liệu""))"),"")
A15: =IF(C15="","",ROW()-5) | J15: =IF(OR(H15="",I15=""),"",MAX(0,I15-H15)) | L15: =IFERROR(__xludf.DUMMYFUNCTION("IF($C15="""","""",IFERROR(INDEX(SORT(FILTER({DATA_GOC!$B$4:$B$49999,DATA_GOC!$P$4:$P$49999,DATA_GOC!$J$4:$J$49999},DATA_GOC!$A$4:$A$49999=""BOM"",TRIM(DATA_GOC!$D$4:$D$49999)=TRIM($C15),DATA_GOC!$J$4:$J$49999<>"""",DATA_GOC!$B$4:$B$49999<=$B$3),1,FALSE,2,"&"FALSE),1,3),""Chưa có dữ liệu""))"),"")
A16: =IF(C16="","",ROW()-5) | J16: =IF(OR(H16="",I16=""),"",MAX(0,I16-H16)) | L16: =IFERROR(__xludf.DUMMYFUNCTION("IF($C16="""","""",IFERROR(INDEX(SORT(FILTER({DATA_GOC!$B$4:$B$49999,DATA_GOC!$P$4:$P$49999,DATA_GOC!$J$4:$J$49999},DATA_GOC!$A$4:$A$49999=""BOM"",TRIM(DATA_GOC!$D$4:$D$49999)=TRIM($C16),DATA_GOC!$J$4:$J$49999<>"""",DATA_GOC!$B$4:$B$49999<=$B$3),1,FALSE,2,"&"FALSE),1,3),""Chưa có dữ liệu""))"),"")
A17: =IF(C17="","",ROW()-5) | J17: =IF(OR(H17="",I17=""),"",MAX(0,I17-H17)) | L17: =IFERROR(__xludf.DUMMYFUNCTION("IF($C17="""","""",IFERROR(INDEX(SORT(FILTER({DATA_GOC!$B$4:$B$49999,DATA_GOC!$P$4:$P$49999,DATA_GOC!$J$4:$J$49999},DATA_GOC!$A$4:$A$49999=""BOM"",TRIM(DATA_GOC!$D$4:$D$49999)=TRIM($C17),DATA_GOC!$J$4:$J$49999<>"""",DATA_GOC!$B$4:$B$49999<=$B$3),1,FALSE,2,"&"FALSE),1,3),""Chưa có dữ liệu""))"),"")
A18: =IF(C18="","",ROW()-5) | J18: =IF(OR(H18="",I18=""),"",MAX(0,I18-H18)) | L18: =IFERROR(__xludf.DUMMYFUNCTION("IF($C18="""","""",IFERROR(INDEX(SORT(FILTER({DATA_GOC!$B$4:$B$49999,DATA_GOC!$P$4:$P$49999,DATA_GOC!$J$4:$J$49999},DATA_GOC!$A$4:$A$49999=""BOM"",TRIM(DATA_GOC!$D$4:$D$49999)=TRIM($C18),DATA_GOC!$J$4:$J$49999<>"""",DATA_GOC!$B$4:$B$49999<=$B$3),1,FALSE,2,"&"FALSE),1,3),""Chưa có dữ liệu""))"),"")
A19: =IF(C19="","",ROW()-5) | J19: =IF(OR(H19="",I19=""),"",MAX(0,I19-H19)) | L19: =IFERROR(__xludf.DUMMYFUNCTION("IF($C19="""","""",IFERROR(INDEX(SORT(FILTER({DATA_GOC!$B$4:$B$49999,DATA_GOC!$P$4:$P$49999,DATA_GOC!$J$4:$J$49999},DATA_GOC!$A$4:$A$49999=""BOM"",TRIM(DATA_GOC!$D$4:$D$49999)=TRIM($C19),DATA_GOC!$J$4:$J$49999<>"""",DATA_GOC!$B$4:$B$49999<=$B$3),1,FALSE,2,"&"FALSE),1,3),""Chưa có dữ liệu""))"),"")
A20: =IF(C20="","",ROW()-5) | J20: =IF(OR(H20="",I20=""),"",MAX(0,I20-H20)) | L20: =IFERROR(__xludf.DUMMYFUNCTION("IF($C20="""","""",IFERROR(INDEX(SORT(FILTER({DATA_GOC!$B$4:$B$49999,DATA_GOC!$P$4:$P$49999,DATA_GOC!$J$4:$J$49999},DATA_GOC!$A$4:$A$49999=""BOM"",TRIM(DATA_GOC!$D$4:$D$49999)=TRIM($C20),DATA_GOC!$J$4:$J$49999<>"""",DATA_GOC!$B$4:$B$49999<=$B$3),1,FALSE,2,"&"FALSE),1,3),""Chưa có dữ liệu""))"),"")
A21: =IF(C21="","",ROW()-5) | J21: =IF(OR(H21="",I21=""),"",MAX(0,I21-H21)) | L21: =IFERROR(__xludf.DUMMYFUNCTION("IF($C21="""","""",IFERROR(INDEX(SORT(FILTER({DATA_GOC!$B$4:$B$49999,DATA_GOC!$P$4:$P$49999,DATA_GOC!$J$4:$J$49999},DATA_GOC!$A$4:$A$49999=""BOM"",TRIM(DATA_GOC!$D$4:$D$49999)=TRIM($C21),DATA_GOC!$J$4:$J$49999<>"""",DATA_GOC!$B$4:$B$49999<=$B$3),1,FALSE,2,"&"FALSE),1,3),""Chưa có dữ liệu""))"),"")
A22: =IF(C22="","",ROW()-5) | J22: =IF(OR(H22="",I22=""),"",MAX(0,I22-H22)) | L22: =IFERROR(__xludf.DUMMYFUNCTION("IF($C22="""","""",IFERROR(INDEX(SORT(FILTER({DATA_GOC!$B$4:$B$49999,DATA_GOC!$P$4:$P$49999,DATA_GOC!$J$4:$J$49999},DATA_GOC!$A$4:$A$49999=""BOM"",TRIM(DATA_GOC!$D$4:$D$49999)=TRIM($C22),DATA_GOC!$J$4:$J$49999<>"""",DATA_GOC!$B$4:$B$49999<=$B$3),1,FALSE,2,"&"FALSE),1,3),""Chưa có dữ liệu""))"),"")
A23: =IF(C23="","",ROW()-5) | J23: =IF(OR(H23="",I23=""),"",MAX(0,I23-H23)) | L23: =IFERROR(__xludf.DUMMYFUNCTION("IF($C23="""","""",IFERROR(INDEX(SORT(FILTER({DATA_GOC!$B$4:$B$49999,DATA_GOC!$P$4:$P$49999,DATA_GOC!$J$4:$J$49999},DATA_GOC!$A$4:$A$49999=""BOM"",TRIM(DATA_GOC!$D$4:$D$49999)=TRIM($C23),DATA_GOC!$J$4:$J$49999<>"""",DATA_GOC!$B$4:$B$49999<=$B$3),1,FALSE,2,"&"FALSE),1,3),""Chưa có dữ liệu""))"),"")
A24: =IF(C24="","",ROW()-5) | J24: =IF(OR(H24="",I24=""),"",MAX(0,I24-H24)) | L24: =IFERROR(__xludf.DUMMYFUNCTION("IF($C24="""","""",IFERROR(INDEX(SORT(FILTER({DATA_GOC!$B$4:$B$49999,DATA_GOC!$P$4:$P$49999,DATA_GOC!$J$4:$J$49999},DATA_GOC!$A$4:$A$49999=""BOM"",TRIM(DATA_GOC!$D$4:$D$49999)=TRIM($C24),DATA_GOC!$J$4:$J$49999<>"""",DATA_GOC!$B$4:$B$49999<=$B$3),1,FALSE,2,"&"FALSE),1,3),""Chưa có dữ liệu""))"),"")
A25: =IF(C25="","",ROW()-5) | J25: =IF(OR(H25="",I25=""),"",MAX(0,I25-H25)) | L25: =IFERROR(__xludf.DUMMYFUNCTION("IF($C25="""","""",IFERROR(INDEX(SORT(FILTER({DATA_GOC!$B$4:$B$49999,DATA_GOC!$P$4:$P$49999,DATA_GOC!$J$4:$J$49999},DATA_GOC!$A$4:$A$49999=""BOM"",TRIM(DATA_GOC!$D$4:$D$49999)=TRIM($C25),DATA_GOC!$J$4:$J$49999<>"""",DATA_GOC!$B$4:$B$49999<=$B$3),1,FALSE,2,"&"FALSE),1,3),""Chưa có dữ liệu""))"),"")
A26: =IF(C26="","",ROW()-5) | J26: =IF(OR(H26="",I26=""),"",MAX(0,I26-H26)) | L26: =IFERROR(__xludf.DUMMYFUNCTION("IF($C26="""","""",IFERROR(INDEX(SORT(FILTER({DATA_GOC!$B$4:$B$49999,DATA_GOC!$P$4:$P$49999,DATA_GOC!$J$4:$J$49999},DATA_GOC!$A$4:$A$49999=""BOM"",TRIM(DATA_GOC!$D$4:$D$49999)=TRIM($C26),DATA_GOC!$J$4:$J$49999<>"""",DATA_GOC!$B$4:$B$49999<=$B$3),1,FALSE,2,"&"FALSE),1,3),""Chưa có dữ liệu""))"),"")
A27: =IF(C27="","",ROW()-5) | J27: =IF(OR(H27="",I27=""),"",MAX(0,I27-H27)) | L27: =IFERROR(__xludf.DUMMYFUNCTION("IF($C27="""","""",IFERROR(INDEX(SORT(FILTER({DATA_GOC!$B$4:$B$49999,DATA_GOC!$P$4:$P$49999,DATA_GOC!$J$4:$J$49999},DATA_GOC!$A$4:$A$49999=""BOM"",TRIM(DATA_GOC!$D$4:$D$49999)=TRIM($C27),DATA_GOC!$J$4:$J$49999<>"""",DATA_GOC!$B$4:$B$49999<=$B$3),1,FALSE,2,"&"FALSE),1,3),""Chưa có dữ liệu""))"),"")
A28: =IF(C28="","",ROW()-5) | J28: =IF(OR(H28="",I28=""),"",MAX(0,I28-H28)) | L28: =IFERROR(__xludf.DUMMYFUNCTION("IF($C28="""","""",IFERROR(INDEX(SORT(FILTER({DATA_GOC!$B$4:$B$49999,DATA_GOC!$P$4:$P$49999,DATA_GOC!$J$4:$J$49999},DATA_GOC!$A$4:$A$49999=""BOM"",TRIM(DATA_GOC!$D$4:$D$49999)=TRIM($C28),DATA_GOC!$J$4:$J$49999<>"""",DATA_GOC!$B$4:$B$49999<=$B$3),1,FALSE,2,"&"FALSE),1,3),""Chưa có dữ liệu""))"),"")
A29: =IF(C29="","",ROW()-5) | J29: =IF(OR(H29="",I29=""),"",MAX(0,I29-H29)) | L29: =IFERROR(__xludf.DUMMYFUNCTION("IF($C29="""","""",IFERROR(INDEX(SORT(FILTER({DATA_GOC!$B$4:$B$49999,DATA_GOC!$P$4:$P$49999,DATA_GOC!$J$4:$J$49999},DATA_GOC!$A$4:$A$49999=""BOM"",TRIM(DATA_GOC!$D$4:$D$49999)=TRIM($C29),DATA_GOC!$J$4:$J$49999<>"""",DATA_GOC!$B$4:$B$49999<=$B$3),1,FALSE,2,"&"FALSE),1,3),""Chưa có dữ liệu""))"),"")
A30: =IF(C30="","",ROW()-5) | J30: =IF(OR(H30="",I30=""),"",MAX(0,I30-H30)) | L30: =IFERROR(__xludf.DUMMYFUNCTION("IF($C30="""","""",IFERROR(INDEX(SORT(FILTER({DATA_GOC!$B$4:$B$49999,DATA_GOC!$P$4:$P$49999,DATA_GOC!$J$4:$J$49999},DATA_GOC!$A$4:$A$49999=""BOM"",TRIM(DATA_GOC!$D$4:$D$49999)=TRIM($C30),DATA_GOC!$J$4:$J$49999<>"""",DATA_GOC!$B$4:$B$49999<=$B$3),1,FALSE,2,"&"FALSE),1,3),""Chưa có dữ liệu""))"),"")
A31: =IF(C31="","",ROW()-5) | J31: =IF(OR(H31="",I31=""),"",MAX(0,I31-H31)) | L31: =IFERROR(__xludf.DUMMYFUNCTION("IF($C31="""","""",IFERROR(INDEX(SORT(FILTER({DATA_GOC!$B$4:$B$49999,DATA_GOC!$P$4:$P$49999,DATA_GOC!$J$4:$J$49999},DATA_GOC!$A$4:$A$49999=""BOM"",TRIM(DATA_GOC!$D$4:$D$49999)=TRIM($C31),DATA_GOC!$J$4:$J$49999<>"""",DATA_GOC!$B$4:$B$49999<=$B$3),1,FALSE,2,"&"FALSE),1,3),""Chưa có dữ liệu""))"),"")
A32: =IF(C32="","",ROW()-5) | J32: =IF(OR(H32="",I32=""),"",MAX(0,I32-H32)) | L32: =IFERROR(__xludf.DUMMYFUNCTION("IF($C32="""","""",IFERROR(INDEX(SORT(FILTER({DATA_GOC!$B$4:$B$49999,DATA_GOC!$P$4:$P$49999,DATA_GOC!$J$4:$J$49999},DATA_GOC!$A$4:$A$49999=""BOM"",TRIM(DATA_GOC!$D$4:$D$49999)=TRIM($C32),DATA_GOC!$J$4:$J$49999<>"""",DATA_GOC!$B$4:$B$49999<=$B$3),1,FALSE,2,"&"FALSE),1,3),""Chưa có dữ liệu""))"),"")
A33: =IF(C33="","",ROW()-5) | J33: =IF(OR(H33="",I33=""),"",MAX(0,I33-H33)) | L33: =IFERROR(__xludf.DUMMYFUNCTION("IF($C33="""","""",IFERROR(INDEX(SORT(FILTER({DATA_GOC!$B$4:$B$49999,DATA_GOC!$P$4:$P$49999,DATA_GOC!$J$4:$J$49999},DATA_GOC!$A$4:$A$49999=""BOM"",TRIM(DATA_GOC!$D$4:$D$49999)=TRIM($C33),DATA_GOC!$J$4:$J$49999<>"""",DATA_GOC!$B$4:$B$49999<=$B$3),1,FALSE,2,"&"FALSE),1,3),""Chưa có dữ liệu""))"),"")
A34: =IF(C34="","",ROW()-5) | J34: =IF(OR(H34="",I34=""),"",MAX(0,I34-H34)) | L34: =IFERROR(__xludf.DUMMYFUNCTION("IF($C34="""","""",IFERROR(INDEX(SORT(FILTER({DATA_GOC!$B$4:$B$49999,DATA_GOC!$P$4:$P$49999,DATA_GOC!$J$4:$J$49999},DATA_GOC!$A$4:$A$49999=""BOM"",TRIM(DATA_GOC!$D$4:$D$49999)=TRIM($C34),DATA_GOC!$J$4:$J$49999<>"""",DATA_GOC!$B$4:$B$49999<=$B$3),1,FALSE,2,"&"FALSE),1,3),""Chưa có dữ liệu""))"),"")
A35: =IF(C35="","",ROW()-5) | J35: =IF(OR(H35="",I35=""),"",MAX(0,I35-H35)) | L35: =IFERROR(__xludf.DUMMYFUNCTION("IF($C35="""","""",IFERROR(INDEX(SORT(FILTER({DATA_GOC!$B$4:$B$49999,DATA_GOC!$P$4:$P$49999,DATA_GOC!$J$4:$J$49999},DATA_GOC!$A$4:$A$49999=""BOM"",TRIM(DATA_GOC!$D$4:$D$49999)=TRIM($C35),DATA_GOC!$J$4:$J$49999<>"""",DATA_GOC!$B$4:$B$49999<=$B$3),1,FALSE,2,"&"FALSE),1,3),""Chưa có dữ liệu""))"),"")
A36: =IF(C36="","",ROW()-5) | J36: =IF(OR(H36="",I36=""),"",MAX(0,I36-H36)) | L36: =IFERROR(__xludf.DUMMYFUNCTION("IF($C36="""","""",IFERROR(INDEX(SORT(FILTER({DATA_GOC!$B$4:$B$49999,DATA_GOC!$P$4:$P$49999,DATA_GOC!$J$4:$J$49999},DATA_GOC!$A$4:$A$49999=""BOM"",TRIM(DATA_GOC!$D$4:$D$49999)=TRIM($C36),DATA_GOC!$J$4:$J$49999<>"""",DATA_GOC!$B$4:$B$49999<=$B$3),1,FALSE,2,"&"FALSE),1,3),""Chưa có dữ liệu""))"),"")
A37: =IF(C37="","",ROW()-5) | J37: =IF(OR(H37="",I37=""),"",MAX(0,I37-H37)) | L37: =IFERROR(__xludf.DUMMYFUNCTION("IF($C37="""","""",IFERROR(INDEX(SORT(FILTER({DATA_GOC!$B$4:$B$49999,DATA_GOC!$P$4:$P$49999,DATA_GOC!$J$4:$J$49999},DATA_GOC!$A$4:$A$49999=""BOM"",TRIM(DATA_GOC!$D$4:$D$49999)=TRIM($C37),DATA_GOC!$J$4:$J$49999<>"""",DATA_GOC!$B$4:$B$49999<=$B$3),1,FALSE,2,"&"FALSE),1,3),""Chưa có dữ liệu""))"),"")
A38: =IF(C38="","",ROW()-5) | J38: =IF(OR(H38="",I38=""),"",MAX(0,I38-H38)) | L38: =IFERROR(__xludf.DUMMYFUNCTION("IF($C38="""","""",IFERROR(INDEX(SORT(FILTER({DATA_GOC!$B$4:$B$49999,DATA_GOC!$P$4:$P$49999,DATA_GOC!$J$4:$J$49999},DATA_GOC!$A$4:$A$49999=""BOM"",TRIM(DATA_GOC!$D$4:$D$49999)=TRIM($C38),DATA_GOC!$J$4:$J$49999<>"""",DATA_GOC!$B$4:$B$49999<=$B$3),1,FALSE,2,"&"FALSE),1,3),""Chưa có dữ liệu""))"),"")
A39: =IF(C39="","",ROW()-5) | J39: =IF(OR(H39="",I39=""),"",MAX(0,I39-H39)) | L39: =IFERROR(__xludf.DUMMYFUNCTION("IF($C39="""","""",IFERROR(INDEX(SORT(FILTER({DATA_GOC!$B$4:$B$49999,DATA_GOC!$P$4:$P$49999,DATA_GOC!$J$4:$J$49999},DATA_GOC!$A$4:$A$49999=""BOM"",TRIM(DATA_GOC!$D$4:$D$49999)=TRIM($C39),DATA_GOC!$J$4:$J$49999<>"""",DATA_GOC!$B$4:$B$49999<=$B$3),1,FALSE,2,"&"FALSE),1,3),""Chưa có dữ liệu""))"),"")
A40: =IF(C40="","",ROW()-5) | J40: =IF(OR(H40="",I40=""),"",MAX(0,I40-H40)) | L40: =IFERROR(__xludf.DUMMYFUNCTION("IF($C40="""","""",IFERROR(INDEX(SORT(FILTER({DATA_GOC!$B$4:$B$49999,DATA_GOC!$P$4:$P$49999,DATA_GOC!$J$4:$J$49999},DATA_GOC!$A$4:$A$49999=""BOM"",TRIM(DATA_GOC!$D$4:$D$49999)=TRIM($C40),DATA_GOC!$J$4:$J$49999<>"""",DATA_GOC!$B$4:$B$49999<=$B$3),1,FALSE,2,"&"FALSE),1,3),""Chưa có dữ liệu""))"),"")
A41: =IF(C41="","",ROW()-5) | J41: =IF(OR(H41="",I41=""),"",MAX(0,I41-H41)) | L41: =IFERROR(__xludf.DUMMYFUNCTION("IF($C41="""","""",IFERROR(INDEX(SORT(FILTER({DATA_GOC!$B$4:$B$49999,DATA_GOC!$P$4:$P$49999,DATA_GOC!$J$4:$J$49999},DATA_GOC!$A$4:$A$49999=""BOM"",TRIM(DATA_GOC!$D$4:$D$49999)=TRIM($C41),DATA_GOC!$J$4:$J$49999<>"""",DATA_GOC!$B$4:$B$49999<=$B$3),1,FALSE,2,"&"FALSE),1,3),""Chưa có dữ liệu""))"),"")
A42: =IF(C42="","",ROW()-5) | J42: =IF(OR(H42="",I42=""),"",MAX(0,I42-H42)) | L42: =IFERROR(__xludf.DUMMYFUNCTION("IF($C42="""","""",IFERROR(INDEX(SORT(FILTER({DATA_GOC!$B$4:$B$49999,DATA_GOC!$P$4:$P$49999,DATA_GOC!$J$4:$J$49999},DATA_GOC!$A$4:$A$49999=""BOM"",TRIM(DATA_GOC!$D$4:$D$49999)=TRIM($C42),DATA_GOC!$J$4:$J$49999<>"""",DATA_GOC!$B$4:$B$49999<=$B$3),1,FALSE,2,"&"FALSE),1,3),""Chưa có dữ liệu""))"),"")
...

Sheet NHAP
A1: NHAP — Nhập dầu vào kho / téc
A3: Ngày | B3: 46209 | C3: ① Điền thông tin bên dưới | D3: → Điền xong nhấn Lưu Nhập
A5: # | B5: Số phiếu/HĐ | C5: Nhà cung cấp | D5: Téc nhận dầu | E5: Loại dầu | F5: Số lít nhập | G5: Đơn giá (đ/L) | H5: Thành tiền | I5: Ghi chú
A6: =IF(D6="","",ROW()-5) | H6: =IF(OR(F6="",G6=""),"",F6*G6)
A7: =IF(D7="","",ROW()-5) | H7: =IF(OR(F7="",G7=""),"",F7*G7)
A8: =IF(D8="","",ROW()-5) | H8: =IF(OR(F8="",G8=""),"",F8*G8)
A9: =IF(D9="","",ROW()-5) | H9: =IF(OR(F9="",G9=""),"",F9*G9)
A10: =IF(D10="","",ROW()-5) | H10: =IF(OR(F10="",G10=""),"",F10*G10)
A11: =IF(D11="","",ROW()-5) | H11: =IF(OR(F11="",G11=""),"",F11*G11)
A12: =IF(D12="","",ROW()-5) | H12: =IF(OR(F12="",G12=""),"",F12*G12)
A13: =IF(D13="","",ROW()-5) | H13: =IF(OR(F13="",G13=""),"",F13*G13)
A14: =IF(D14="","",ROW()-5) | H14: =IF(OR(F14="",G14=""),"",F14*G14)
A15: =IF(D15="","",ROW()-5) | H15: =IF(OR(F15="",G15=""),"",F15*G15)
A16: =IF(D16="","",ROW()-5) | H16: =IF(OR(F16="",G16=""),"",F16*G16)
A17: =IF(D17="","",ROW()-5) | H17: =IF(OR(F17="",G17=""),"",F17*G17)
... A55: =IF(D55="","",ROW()-5) | H55: =IF(OR(F55="",G55=""),"",F55*G55)

Sheet TINH_TEC
A1: TỊNH TÉC — Chốt tịnh âm / tịnh dương | AM1: Số xe đang phân bổ
AM2: =MIN(60,COUNTA(DANH_MUC!$E$4:$E$997)) -> 60
A3: Tồn sổ (J) = Tồn đầu F + Nhập H − Xuất I | Tịnh âm (K) = MAX(0, J − G thực tế) | Tịnh dương (L) = MAX(0, G − J) | Q3: Dropdown R5 đã được chuẩn hóa bằng named range LIST_KY_TINH; Cột C dùng LIST_TEC_NGUON. | AM3: Capacity kỳ tịnh: 150; capacity xe: 60
Q4: 2) DASHBOARD TỊNH ĐANG XEM
A5: Kỳ ID | B5: Trạng thái | C5: Téc | D5: Ngày bắt đầu | E5: Ngày chốt/hết | F5: Tồn đầu còn sót (tự nhập) | G5: Tồn thực tế ← KT kho nhập | H5: Nhập kỳ (tự tính) | I5: Xuất ĐH (tự tính) | J5: Tồn sổ (tự tính) | K5: Tịnh âm (tự tính) | L5: Tịnh dương (tự tính) | M5: Tháng | N5: Năm | O5: Ghi chú | Q5: Chọn KyTinhID | R5: 1 | S5: Trạng thái | T5: {=IFERROR(INDEX($B$6:$B$155,MATCH($R$5,$A$6:$A$155,0)),"")} -> Đã chốt | U5: Téc | V5: {=IFERROR(INDEX($C$6:$C$155,MATCH($R$5,$A$6:$A$155,0)),"")} -> Téc 1 | W5: Từ ngày | X5: {=IFERROR(INDEX($D$6:$D$155,MATCH($R$5,$A$6:$A$155,0)),"")} -> 46132 | Y5: Đến ngày | Z5: {=IFERROR(INDEX($E$6:$E$155,MATCH($R$5,$A$6:$A$155,0)),"")} -> 46153 | AA5: Số ngày | AB5: =IF(OR($X$5="",$Z$5=""),"",$Z$5-$X$5+1) -> 22
A6: 1 | B6: Đã chốt | C6: Téc 1 | D6: 46132 | E6: 46153 | H6: =IF(OR($C6="",$D6="",$E6=""),"",SUMIFS(DATA_GOC!$H:$H,DATA_GOC!$A:$A,"NHAP",DATA_GOC!$E:$E,$C6,DATA_GOC!$B:$B,">="&$D6,DATA_GOC!$B:$B,"<="&$E6)) -> 14160 | I6: =IF(OR($C6="",$D6="",$E6=""),"",SUMIFS(DATA_GOC!$H:$H,DATA_GOC!$A:$A,"BOM",DATA_GOC!$E:$E,$C6,DATA_GOC!$F:$F,"Xuất nội bộ từ téc",DATA_GOC!$B:$B,">="&$D6,DATA_GOC!$B:$B,"<="&$E6)) -> 13789 | J6: =IF($I6="","",N($F6)+N($H6)-N($I6)) -> 371 | K6: =IF($J6="","",MAX(0,N($J6)-N($G6))) -> 371 | L6: =IF($J6="","",MAX(0,N($G6)-N($J6))) -> 0 | M6: =IF($E6="","",MONTH($E6)) -> 5 | N6: =IF($E6="","",YEAR($E6)) -> 2026
A7: 2 | B7: Đã chốt | C7: Téc 1 | D7: 46082 | E7: 46121 | H7: =IF(OR($C7="",$D7="",$E7=""),"",SUMIFS(DATA_GOC!$H:$H,DATA_GOC!$A:$A,"NHAP",DATA_GOC!$E:$E,$C7,DATA_GOC!$B:$B,">="&$D7,DATA_GOC!$B:$B,"<="&$E7)) -> 8745 | I7: =IF(OR($C7="",$D7="",$E7=""),"",SUMIFS(DATA_GOC!$H:$H,DATA_GOC!$A:$A,"BOM",DATA_GOC!$E:$E,$C7,DATA_GOC!$F:$F,"Xuất nội bộ từ téc",DATA_GOC!$B:$B,">="&$D7,DATA_GOC!$B:$B,"<="&$E7)) -> 8680 | J7: =IF($I7="","",N($F7)+N($H7)-N($I7)) -> 65 | K7: =IF($J7="","",MAX(0,N($J7)-N($G7))) -> 65 | L7: =IF($J7="","",MAX(0,N($G7)-N($J7))) -> 0 | M7: =IF($E7="","",MONTH($E7)) -> 4 | N7: =IF($E7="","",YEAR($E7)) -> 2026 | Q7: Tồn đầu/sót | T7: Nhập trong kỳ | W7: Xuất đồng hồ | Z7: Tồn sổ trước chốt | AC7: Tồn thực tế | AF7: Tịnh âm tổng | AI7: Tịnh dương tổng
A8: 3 | B8: Đã chốt | C8: Téc 1 | D8: 46056 | E8: 46079 | H8: =IF(OR($C8="",$D8="",$E8=""),"",SUMIFS(DATA_GOC!$H:$H,DATA_GOC!$A:$A,"NHAP",DATA_GOC!$E:$E,$C8,DATA_GOC!$B:$B,">="&$D8,DATA_GOC!$B:$B,"<="&$E8)) -> 11173 | I8: =IF(OR($C8="",$D8="",$E8=""),"",SUMIFS(DATA_GOC!$H:$H,DATA_GOC!$A:$A,"BOM",DATA_GOC!$E:$E,$C8,DATA_GOC!$F:$F,"Xuất nội bộ từ téc",DATA_GOC!$B:$B,">="&$D8,DATA_GOC!$B:$B,"<="&$E8)) -> 10823 | J8: =IF($I8="","",N($F8)+N($H8)-N($I8)) -> 350 | K8: =IF($J8="","",MAX(0,N($J8)-N($G8))) -> 350 | L8: =IF($J8="","",MAX(0,N($G8)-N($J8))) -> 0 | M8: =IF($E8="","",MONTH($E8)) -> 2 | N8: =IF($E8="","",YEAR($E8)) -> 2026 | Q8: {=IFERROR(INDEX($F$6:$F$155,MATCH($R$5,$A$6:$A$155,0)),"")} | T8: {=IFERROR(INDEX($H$6:$H$155,MATCH($R$5,$A$6:$A$155,0)),"")} -> 14160 | W8: {=IFERROR(INDEX($I$6:$I$155,MATCH($R$5,$A$6:$A$155,0)),"")} -> 13789 | Z8: {=IFERROR(INDEX($J$6:$J$155,MATCH($R$5,$A$6:$A$155,0)),"")} -> 371 | AC8: {=IFERROR(INDEX($G$6:$G$155,MATCH($R$5,$A$6:$A$155,0)),"")} | AF8: {=IFERROR(INDEX($K$6:$K$155,MATCH($R$5,$A$6:$A$155,0)),"")} -> 371 | AI8: {=IFERROR(INDEX($L$6:$L$155,MATCH($R$5,$A$6:$A$155,0)),"")} -> 0
A9: 4 | B9: Đã chốt | C9: Téc 2 | D9: 46023 | E9: 46035 | F9: 104 | H9: =IF(OR($C9="",$D9="",$E9=""),"",SUMIFS(DATA_GOC!$H:$H,DATA_GOC!$A:$A,"NHAP",DATA_GOC!$E:$E,$C9,DATA_GOC!$B:$B,">="&$D9,DATA_GOC!$B:$B,"<="&$E9)) -> 21270 | I9: =IF(OR($C9="",$D9="",$E9=""),"",SUMIFS(DATA_GOC!$H:$H,DATA_GOC!$A:$A,"BOM",DATA_GOC!$E:$E,$C9,DATA_GOC!$F:$F,"Xuất nội bộ từ téc",DATA_GOC!$B:$B,">="&$D9,DATA_GOC!$B:$B,"<="&$E9)) -> 20617 | J9: =IF($I9="","",N($F9)+N($H9)-N($I9)) -> 757 | K9: =IF($J9="","",MAX(0,N($J9)-N($G9))) -> 757 | L9: =IF($J9="","",MAX(0,N($G9)-N($J9))) -> 0 | M9: =IF($E9="","",MONTH($E9)) -> 1 | N9: =IF($E9="","",YEAR($E9)) -> 2026
A10: 5 | B10: Đã chốt | C10: Téc 2 | D10: 46046 | E10: 46057 | H10: =IF(OR($C10="",$D10="",$E10=""),"",SUMIFS(DATA_GOC!$H:$H,DATA_GOC!$A:$A,"NHAP",DATA_GOC!$E:$E,$C10,DATA_GOC!$B:$B,">="&$D10,DATA_GOC!$B:$B,"<="&$E10)) -> 22930 | I10: =IF(OR($C10="",$D10="",$E10=""),"",SUMIFS(DATA_GOC!$H:$H,DATA_GOC!$A:$A,"BOM",DATA_GOC!$E:$E,$C10,DATA_GOC!$F:$F,"Xuất nội bộ từ téc",DATA_GOC!$B:$B,">="&$D10,DATA_GOC!$B:$B,"<="&$E10)) -> 22574 | J10: =IF($I10="","",N($F10)+N($H10)-N($I10)) -> 356 | K10: =IF($J10="","",MAX(0,N($J10)-N($G10))) -> 356 | L10: =IF($J10="","",MAX(0,N($G10)-N($J10))) -> 0 | M10: =IF($E10="","",MONTH($E10)) -> 2 | N10: =IF($E10="","",YEAR($E10)) -> 2026 | Q10: # | R10: Xe / phương tiện | S10: Lít bơm kỳ | T10: Tỷ trọng | U10: Tịnh âm PB | V10: Tịnh dương PB | W10: Tiêu hao sau tịnh
A11: 6 | B11: Đã chốt | C11: Téc 2 | D11: 46058 | E11: 46079 | H11: =IF(OR($C11="",$D11="",$E11=""),"",SUMIFS(DATA_GOC!$H:$H,DATA_GOC!$A:$A,"NHAP",DATA_GOC!$E:$E,$C11,DATA_GOC!$B:$B,">="&$D11,DATA_GOC!$B:$B,"<="&$E11)) -> 8745 | I11: =IF(OR($C11="",$D11="",$E11=""),"",SUMIFS(DATA_GOC!$H:$H,DATA_GOC!$A:$A,"BOM",DATA_GOC!$E:$E,$C11,DATA_GOC!$F:$F,"Xuất nội bộ từ téc",DATA_GOC!$B:$B,">="&$D11,DATA_GOC!$B:$B,"<="&$E11)) -> 8473 | J11: =IF($I11="","",N($F11)+N($H11)-N($I11)) -> 272 | K11: =IF($J11="","",MAX(0,N($J11)-N($G11))) -> 272 | L11: =IF($J11="","",MAX(0,N($G11)-N($J11))) -> 0 | M11: =IF($E11="","",MONTH($E11)) -> 2 | N11: =IF($E11="","",YEAR($E11)) -> 2026 | Q11: =IF($B168="","",$A168) -> 1 | R11: =IF($B168="","",$B168) -> 19H09482 | S11: =IF($B168="","",$AH168) -> 480 | T11: =IF($B168="","",$AI168) -> 0.034810356 | U11: =IF($B168="","",$AJ168) -> 12.915 | V11: =IF($B168="","",$AK168) -> 0 | W11: =IF($B168="","",$AL168) -> 492.915
A12: 7 | B12: Đã chốt | C12: Téc 2 | D12: 46082 | E12: 46118 | H12: =IF(OR($C12="",$D12="",$E12=""),"",SUMIFS(DATA_GOC!$H:$H,DATA_GOC!$A:$A,"NHAP",DATA_GOC!$E:$E,$C12,DATA_GOC!$B:$B,">="&$D12,DATA_GOC!$B:$B,"<="&$E12)) -> 29435 | I12: =IF(OR($C12="",$D12="",$E12=""),"",SUMIFS(DATA_GOC!$H:$H,DATA_GOC!$A:$A,"BOM",DATA_GOC!$E:$E,$C12,DATA_GOC!$F:$F,"Xuất nội bộ từ téc",DATA_GOC!$B:$B,">="&$D12,DATA_GOC!$B:$B,"<="&$E12)) -> 28426 | J12: =IF($I12="","",N($F12)+N($H12)-N($I12)) -> 1009 | K12: =IF($J12="","",MAX(0,N($J12)-N($G12))) -> 1009 | L12: =IF($J12="","",MAX(0,N($G12)-N($J12))) -> 0 | M12: =IF($E12="","",MONTH($E12)) -> 4 | N12: =IF($E12="","",YEAR($E12)) -> 2026 | Q12: =IF($B169="","",$A169) -> 2 | R12: =IF($B169="","",$B169) -> 28A30696 | S12: =IF($B169="","",$AH169) -> 35 | T12: =IF($B169="","",$AI169) -> 0.0025382551 | U12: =IF($B169="","",$AJ169) -> 0.942 | V12: =IF($B169="","",$AK169) -> 0 | W12: =IF($B169="","",$AL169) -> 35.942
A13: 8 | B13: Đã chốt | C13: Téc 2 | D13: 46123 | E13: 46142 | H13: =IF(OR($C13="",$D13="",$E13=""),"",SUMIFS(DATA_GOC!$H:$H,DATA_GOC!$A:$A,"NHAP",DATA_GOC!$E:$E,$C13,DATA_GOC!$B:$B,">="&$D13,DATA_GOC!$B:$B,"<="&$E13)) -> 31700 | I13: =IF(OR($C13="",$D13="",$E13=""),"",SUMIFS(DATA_GOC!$H:$H,DATA_GOC!$A:$A,"BOM",DATA_GOC!$E:$E,$C13,DATA_GOC!$F:$F,"Xuất nội bộ từ téc",DATA_GOC!$B:$B,">="&$D13,DATA_GOC!$B:$B,"<="&$E13)) -> 30401 | J13: =IF($I13="","",N($F13)+N($H13)-N($I13)) -> 1299 | K13: =IF($J13="","",MAX(0,N($J13)-N($G13))) -> 1299 | L13: =IF($J13="","",MAX(0,N($G13)-N($J13))) -> 0 | M13: =IF($E13="","",MONTH($E13)) -> 4 | N13: =IF($E13="","",YEAR($E13)) -> 2026 | Q13: =IF($B170="","",$A170) -> 3 | R13: =IF($B170="","",$B170) -> 28C00462 | S13: =IF($B170="","",$AH170) -> 107 | T13: =IF($B170="","",$AI170) -> 0.0077598085 | U13: =IF($B170="","",$AJ170) -> 2.879 | V13: =IF($B170="","",$AK170) -> 0 | W13: =IF($B170="","",$AL170) -> 109.879
A14: 9 | B14: Đã chốt | C14: Téc 3 | D14: 46023 | E14: 46027 | F14: 5779 | H14: =IF(OR($C14="",$D14="",$E14=""),"",SUMIFS(DATA_GOC!$H:$H,DATA_GOC!$A:$A,"NHAP",DATA_GOC!$E:$E,$C14,DATA_GOC!$B:$B,">="&$D14,DATA_GOC!$B:$B,"<="&$E14)) -> 0 | I14: =IF(OR($C14="",$D14="",$E14=""),"",SUMIFS(DATA_GOC!$H:$H,DATA_GOC!$A:$A,"BOM",DATA_GOC!$E:$E,$C14,DATA_GOC!$F:$F,"Xuất nội bộ từ téc",DATA_GOC!$B:$B,">="&$D14,DATA_GOC!$B:$B,"<="&$E14)) -> 5395 | J14: =IF($I14="","",N($F14)+N($H14)-N($I14)) -> 384 | K14: =IF($J14="","",MAX(0,N($J14)-N($G14))) -> 384 | L14: =IF($J14="","",MAX(0,N($G14)-N($J14))) -> 0 | M14: =IF($E14="","",MONTH($E14)) -> 1 | N14: =IF($E14="","",YEAR($E14)) -> 2026 | Q14: =IF($B171="","",$A171) -> 4 | R14: =IF($B171="","",$B171) -> 28C01165 | S14: =IF($B171="","",$AH171) -> 0 | T14: =IF($B171="","",$AI171) -> 0 | U14: =IF($B171="","",$AJ171) -> 0 | V14: =IF($B171="","",$AK171) -> 0 | W14: =IF($B171="","",$AL171) -> 0
A15: 10 | B15: Đã chốt | C15: Téc 3 | D15: 46028 | E15: 46046 | H15: =IF(OR($C15="",$D15="",$E15=""),"",SUMIFS(DATA_GOC!$H:$H,DATA_GOC!$A:$A,"NHAP",DATA_GOC!$E:$E,$C15,DATA_GOC!$B:$B,">="&$D15,DATA_GOC!$B:$B,"<="&$E15)) -> 22335 | I15: =IF(OR($C15="",$D15="",$E15=""),"",SUMIFS(DATA_GOC!$H:$H,DATA_GOC!$A:$A,"BOM",DATA_GOC!$E:$E,$C15,DATA_GOC!$F:$F,"Xuất nội bộ từ téc",DATA_GOC!$B:$B,">="&$D15,DATA_GOC!$B:$B,"<="&$E15)) -> 21509 | J15: =IF($I15="","",N($F15)+N($H15)-N($I15)) -> 826 | K15: =IF($J15="","",MAX(0,N($J15)-N($G15))) -> 826 | L15: =IF($J15="","",MAX(0,N($G15)-N($J15))) -> 0 | M15: =IF($E15="","",MONTH($E15)) -> 1 | N15: =IF($E15="","",YEAR($E15)) -> 2026 | Q15: =IF($B172="","",$A172) -> 5 | R15: =IF($B172="","",$B172) -> 28C01406 | S15: =IF($B172="","",$AH172) -> 370 | T15: =IF($B172="","",$AI172) -> 0.026832983 | U15: =IF($B172="","",$AJ172) -> 9.955 | V15: =IF($B172="","",$AK172) -> 0 | W15: =IF($B172="","",$AL172) -> 379.955
A16: 11 | B16: Đã chốt | C16: Téc 3 | D16: 46065 | E16: 46106 | H16: =IF(OR($C16="",$D16="",$E16=""),"",SUMIFS(DATA_GOC!$H:$H,DATA_GOC!$A:$A,"NHAP",DATA_GOC!$E:$E,$C16,DATA_GOC!$B:$B,">="&$D16,DATA_GOC!$B:$B,"<="&$E16)) -> 30130 | I16: =IF(OR($C16="",$D16="",$E16=""),"",SUMIFS(DATA_GOC!$H:$H,DATA_GOC!$A:$A,"BOM",DATA_GOC!$E:$E,$C16,DATA_GOC!$F:$F,"Xuất nội bộ từ téc",DATA_GOC!$B:$B,">="&$D16,DATA_GOC!$B:$B,"<="&$E16)) -> 29125 | J16: =IF($I16="","",N($F16)+N($H16)-N($I16)) -> 1005 | K16: =IF($J16="","",MAX(0,N($J16)-N($G16))) -> 1005 | L16: =IF($J16="","",MAX(0,N($G16)-N($J16))) -> 0 | M16: =IF($E16="","",MONTH($E16)) -> 3 | N16: =IF($E16="","",YEAR($E16)) -> 2026 | Q16: =IF($B173="","",$A173) -> 6 | R16: =IF($B173="","",$B173) -> 28C01544 | S16: =IF($B173="","",$AH173) -> 46 | T16: =IF($B173="","",$AI173) -> 0.0033359925 | U16: =IF($B173="","",$AJ173) -> 1.238 | V16: =IF($B173="","",$AK173) -> 0 | W16: =IF($B173="","",$AL173) -> 47.238
A17: 12 | B17: Đã chốt | C17: Téc 3 | D17: 46111 | E17: 46128 | H17: =IF(OR($C17="",$D17="",$E17=""),"",SUMIFS(DATA_GOC!$H:$H,DATA_GOC!$A:$A,"NHAP",DATA_GOC!$E:$E,$C17,DATA_GOC!$B:$B,">="&$D17,DATA_GOC!$B:$B,"<="&$E17)) -> 15850 | I17: =IF(OR($C17="",$D17="",$E17=""),"",SUMIFS(DATA_GOC!$H:$H,DATA_GOC!$A:$A,"BOM",DATA_GOC!$E:$E,$C17,DATA_GOC!$F:$F,"Xuất nội bộ từ téc",DATA_GOC!$B:$B,">="&$D17,DATA_GOC!$B:$B,"<="&$E17)) -> 15710 | J17: =IF($I17="","",N($F17)+N($H17)-N($I17)) -> 140 | K17: =IF($J17="","",MAX(0,N($J17)-N($G17))) -> 140 | L17: =IF($J17="","",MAX(0,N($G17)-N($J17))) -> 0 | M17: =IF($E17="","",MONTH($E17)) -> 4 | N17: =IF($E17="","",YEAR($E17)) -> 2026 | Q17: =IF($B174="","",$A174) -> 7 | R17: =IF($B174="","",$B174) -> 28C01622 | S17: =IF($B174="","",$AH174) -> 740 | T17: =IF($B174="","",$AI174) -> 0.053665966 | U17: =IF($B174="","",$AJ174) -> 19.91 | V17: =IF($B174="","",$AK174) -> 0 | W17: =IF($B174="","",$AL174) -> 759.91
A18: 13 | B18: Đã chốt | C18: Téc 3 | D18: 46131 | E18: 46165 | H18: =IF(OR($C18="",$D18="",$E18=""),"",SUMIFS(DATA_GOC!$H:$H,DATA_GOC!$A:$A,"NHAP",DATA_GOC!$E:$E,$C18,DATA_GOC!$B:$B,">="&$D18,DATA_GOC!$B:$B,"<="&$E18)) -> 30015 | I18: =IF(OR($C18="",$D18="",$E18=""),"",SUMIFS(DATA_GOC!$H:$H,DATA_GOC!$A:$A,"BOM",DATA_GOC!$E:$E,$C18,DATA_GOC!$F:$F,"Xuất nội bộ từ téc",DATA_GOC!$B:$B,">="&$D18,DATA_GOC!$B:$B,"<="&$E18)) -> 29077 | J18: =IF($I18="","",N($F18)+N($H18)-N($I18)) -> 938 | K18: =IF($J18="","",MAX(0,N($J18)-N($G18))) -> 938 | L18: =IF($J18="","",MAX(0,N($G18)-N($J18))) -> 0 | M18: =IF($E18="","",MONTH($E18)) -> 5 | N18: =IF($E18="","",YEAR($E18)) -> 2026 | Q18: =IF($B175="","",$A175) -> 8 | R18: =IF($B175="","",$B175) -> 28C01647 | S18: =IF($B175="","",$AH175) -> 444 | T18: =IF($B175="","",$AI175) -> 0.032199579 | U18: =IF($B175="","",$AJ175) -> 11.946 | V18: =IF($B175="","",$AK175) -> 0 | W18: =IF($B175="","",$AL175) -> 455.946
A19: 14 | B19: Đã chốt | C19: Téc 1 | D19: 46162 | E19: 46168 | H19: =IF(OR($C19="",$D19="",$E19=""),"",SUMIFS(DATA_GOC!$H:$H,DATA_GOC!$A:$A,"NHAP",DATA_GOC!$E:$E,$C19,DATA_GOC!$B:$B,">="&$D19,DATA_GOC!$B:$B,"<="&$E19)) -> 8134 | I19: =IF(OR($C19="",$D19="",$E19=""),"",SUMIFS(DATA_GOC!$H:$H,DATA_GOC!$A:$A,"BOM",DATA_GOC!$E:$E,$C19,DATA_GOC!$F:$F,"Xuất nội bộ từ téc",DATA_GOC!$B:$B,">="&$D19,DATA_GOC!$B:$B,"<="&$E19)) -> 7755 | J19: =IF($I19="","",N($F19)+N($H19)-N($I19)) -> 379 | K19: =IF($J19="","",MAX(0,N($J19)-N($G19))) -> 379 | L19: =IF($J19="","",MAX(0,N($G19)-N($J19))) -> 0 | M19: =IF($E19="","",MONTH($E19)) -> 5 | N19: =IF($E19="","",YEAR($E19)) -> 2026 | Q19: =IF($B176="","",$A176) -> 9 | R19: =IF($B176="","",$B176) -> 28C01731 | S19: =IF($B176="","",$AH176) -> 247 | T19: =IF($B176="","",$AI176) -> 0.017912829 | U19: =IF($B176="","",$AJ176) -> 6.646 | V19: =IF($B176="","",$AK176) -> 0 | W19: =IF($B176="","",$AL176) -> 253.646
A20: 15 | B20: Đã chốt | C20: Téc 2 | D20: 46160 | E20: 46184 | F20: =IF(OR($C20="",$D20=""),"",IFERROR(LOOKUP(2,1/(($C$6:$C$155=$C20)*($B$6:$B$155="Đã chốt")*($E$6:$E$155<$D20)*($G$6:$G$155<>"")),$G$6:$G$155),"")) | H20: =IF(OR($C20="",$D20="",$E20=""),"",SUMIFS(DATA_GOC!$H:$H,DATA_GOC!$A:$A,"NHAP",DATA_GOC!$E:$E,$C20,DATA_GOC!$B:$B,">="&$D20,DATA_GOC!$B:$B,"<="&$E20)) -> 35996 | I20: =IF(OR($C20="",$D20="",$E20=""),"",SUMIFS(DATA_GOC!$H:$H,DATA_GOC!$A:$A,"BOM",DATA_GOC!$E:$E,$C20,DATA_GOC!$F:$F,"Xuất nội bộ từ téc",DATA_GOC!$B:$B,">="&$D20,DATA_GOC!$B:$B,"<="&$E20)) -> 34366 | J20: =IF($I20="","",N($F20)+N($H20)-N($I20)) -> 1630 | K20: =IF($J20="","",MAX(0,N($J20)-N($G20))) -> 1630 | L20: =IF($J20="","",MAX(0,N($G20)-N($J20))) -> 0 | M20: =IF($E20="","",MONTH($E20)) -> 6 | N20: =IF($E20="","",YEAR($E20)) -> 2026 | Q20: =IF($B177="","",$A177) -> 10 | R20: =IF($B177="","",$B177) -> 28C01743 | S20: =IF($B177="","",$AH177) -> 0 | T20: =IF($B177="","",$AI177) -> 0 | U20: =IF($B177="","",$AJ177) -> 0 | V20: =IF($B177="","",$AK177) -> 0 | W20: =IF($B177="","",$AL177) -> 0
A21: 16 | B21: Đã chốt | C21: Téc 1 | D21: 46178 | E21: 46188 | F21: =IF(OR($C21="",$D21=""),"",IFERROR(LOOKUP(2,1/(($C$6:$C$155=$C21)*($B$6:$B$155="Đã chốt")*($E$6:$E$155<$D21)*($G$6:$G$155<>"")),$G$6:$G$155),"")) | H21: =IF(OR($C21="",$D21="",$E21=""),"",SUMIFS(DATA_GOC!$H:$H,DATA_GOC!$A:$A,"NHAP",DATA_GOC!$E:$E,$C21,DATA_GOC!$B:$B,">="&$D21,DATA_GOC!$B:$B,"<="&$E21)) -> 8745 | I21: =IF(OR($C21="",$D21="",$E21=""),"",SUMIFS(DATA_GOC!$H:$H,DATA_GOC!$A:$A,"BOM",DATA_GOC!$E:$E,$C21,DATA_GOC!$F:$F,"Xuất nội bộ từ téc",DATA_GOC!$B:$B,">="&$D21,DATA_GOC!$B:$B,"<="&$E21)) -> 8377 | J21: =IF($I21="","",N($F21)+N($H21)-N($I21)) -> 368 | K21: =IF($J21="","",MAX(0,N($J21)-N($G21))) -> 368 | L21: =IF($J21="","",MAX(0,N($G21)-N($J21))) -> 0 | M21: =IF($E21="","",MONTH($E21)) -> 6 | N21: =IF($E21="","",YEAR($E21)) -> 2026 | Q21: =IF($B178="","",$A178) -> 11 | R21: =IF($B178="","",$B178) -> 28C02106 | S21: =IF($B178="","",$AH178) -> 0 | T21: =IF($B178="","",$AI178) -> 0 | U21: =IF($B178="","",$AJ178) -> 0 | V21: =IF($B178="","",$AK178) -> 0 | W21: =IF($B178="","",$AL178) -> 0
A22: 17 | B22: Đã chốt | C22: Téc 3 | D22: 46178 | E22: 46199 | F22: =IF(OR($C22="",$D22=""),"",IFERROR(LOOKUP(2,1/(($C$6:$C$155=$C22)*($B$6:$B$155="Đã chốt")*($E$6:$E$155<$D22)*($G$6:$G$155<>"")),$G$6:$G$155),"")) | H22: =IF(OR($C22="",$D22="",$E22=""),"",SUMIFS(DATA_GOC!$H:$H,DATA_GOC!$A:$A,"NHAP",DATA_GOC!$E:$E,$C22,DATA_GOC!$B:$B,">="&$D22,DATA_GOC!$B:$B,"<="&$E22)) -> 29415 | I22: =IF(OR($C22="",$D22="",$E22=""),"",SUMIFS(DATA_GOC!$H:$H,DATA_GOC!$A:$A,"BOM",DATA_GOC!$E:$E,$C22,DATA_GOC!$F:$F,"Xuất nội bộ từ téc",DATA_GOC!$B:$B,">="&$D22,DATA_GOC!$B:$B,"<="&$E22)) -> 27987 | J22: =IF($I22="","",N($F22)+N($H22)-N($I22)) -> 1428 | K22: =IF($J22="","",MAX(0,N($J22)-N($G22))) -> 1428 | L22: =IF($J22="","",MAX(0,N($G22)-N($J22))) -> 0 | M22: =IF($E22="","",MONTH($E22)) -> 6 | N22: =IF($E22="","",YEAR($E22)) -> 2026 | Q22: =IF($B179="","",$A179) -> 12 | R22: =IF($B179="","",$B179) -> 28C02410 | S22: =IF($B179="","",$AH179) -> 140 | T22: =IF($B179="","",$AI179) -> 0.010153021 | U22: =IF($B179="","",$AJ179) -> 3.767 | V22: =IF($B179="","",$AK179) -> 0 | W22: =IF($B179="","",$AL179) -> 143.767
A23: 18 | B23: Đã chốt | C23: Téc 2 | D23: 46196 | E23: 46207 | F23: =IF(OR($C23="",$D23=""),"",IFERROR(LOOKUP(2,1/(($C$6:$C$155=$C23)*($B$6:$B$155="Đã chốt")*($E$6:$E$155<$D23)*($G$6:$G$155<>"")),$G$6:$G$155),"")) | H23: =IF(OR($C23="",$D23="",$E23=""),"",SUMIFS(DATA_GOC!$H:$H,DATA_GOC!$A:$A,"NHAP",DATA_GOC!$E:$E,$C23,DATA_GOC!$B:$B,">="&$D23,DATA_GOC!$B:$B,"<="&$E23)) -> 22930 | I23: =IF(OR($C23="",$D23="",$E23=""),"",SUMIFS(DATA_GOC!$H:$H,DATA_GOC!$A:$A,"BOM",DATA_GOC!$E:$E,$C23,DATA_GOC!$F:$F,"Xuất nội bộ từ téc",DATA_GOC!$B:$B,">="&$D23,DATA_GOC!$B:$B,"<="&$E23)) -> 21668 | J23: =IF($I23="","",N($F23)+N($H23)-N($I23)) -> 1262 | K23: =IF($J23="","",MAX(0,N($J23)-N($G23))) -> 1262 | L23: =IF($J23="","",MAX(0,N($G23)-N($J23))) -> 0 | M23: =IF($E23="","",MONTH($E23)) -> 7 | N23: =IF($E23="","",YEAR($E23)) -> 2026 | Q23: =IF($B180="","",$A180) -> 13 | R23: =IF($B180="","",$B180) -> 28C02545 | S23: =IF($B180="","",$AH180) -> 163 | T23: =IF($B180="","",$AI180) -> 0.011821017 | U23: =IF($B180="","",$AJ180) -> 4.386 | V23: =IF($B180="","",$AK180) -> 0 | W23: =IF($B180="","",$AL180) -> 167.386
A24: 19 | F24: =IF(OR($C24="",$D24=""),"",IFERROR(LOOKUP(2,1/(($C$6:$C$155=$C24)*($B$6:$B$155="Đã chốt")*($E$6:$E$155<$D24)*($G$6:$G$155<>"")),$G$6:$G$155),"")) | H24: =IF(OR($C24="",$D24="",$E24=""),"",SUMIFS(DATA_GOC!$H:$H,DATA_GOC!$A:$A,"NHAP",DATA_GOC!$E:$E,$C24,DATA_GOC!$B:$B,">="&$D24,DATA_GOC!$B:$B,"<="&$E24)) | I24: =IF(OR($C24="",$D24="",$E24=""),"",SUMIFS(DATA_GOC!$H:$H,DATA_GOC!$A:$A,"BOM",DATA_GOC!$E:$E,$C24,DATA_GOC!$F:$F,"Xuất nội bộ từ téc",DATA_GOC!$B:$B,">="&$D24,DATA_GOC!$B:$B,"<="&$E24)) | J24: =IF($I24="","",N($F24)+N($H24)-N($I24)) | K24: =IF($J24="","",MAX(0,N($J24)-N($G24))) | L24: =IF($J24="","",MAX(0,N($G24)-N($J24))) | M24: =IF($E24="","",MONTH($E24)) | N24: =IF($E24="","",YEAR($E24)) | Q24: =IF($B181="","",$A181) -> 14 | R24: =IF($B181="","",$B181) -> 28C02574 | S24: =IF($B181="","",$AH181) -> 0 | T24: =IF($B181="","",$AI181) -> 0 | U24: =IF($B181="","",$AJ181) -> 0 | V24: =IF($B181="","",$AK181) -> 0 | W24: =IF($B181="","",$AL181) -> 0
A25: 20 | F25: =IF(OR($C25="",$D25=""),"",IFERROR(LOOKUP(2,1/(($C$6:$C$155=$C25)*($B$6:$B$155="Đã chốt")*($E$6:$E$155<$D25)*($G$6:$G$155<>"")),$G$6:$G$155),"")) | H25: =IF(OR($C25="",$D25="",$E25=""),"",SUMIFS(DATA_GOC!$H:$H,DATA_GOC!$A:$A,"NHAP",DATA_GOC!$E:$E,$C25,DATA_GOC!$B:$B,">="&$D25,DATA_GOC!$B:$B,"<="&$E25)) | I25: =IF(OR($C25="",$D25="",$E25=""),"",SUMIFS(DATA_GOC!$H:$H,DATA_GOC!$A:$A,"BOM",DATA_GOC!$E:$E,$C25,DATA_GOC!$F:$F,"Xuất nội bộ từ téc",DATA_GOC!$B:$B,">="&$D25,DATA_GOC!$B:$B,"<="&$E25)) | J25: =IF($I25="","",N($F25)+N($H25)-N($I25)) | K25: =IF($J25="","",MAX(0,N($J25)-N($G25))) | L25: =IF($J25="","",MAX(0,N($G25)-N($J25))) | M25: =IF($E25="","",MONTH($E25)) | N25: =IF($E25="","",YEAR($E25)) | Q25: =IF($B182="","",$A182) -> 15 | R25: =IF($B182="","",$B182) -> 28C02770 | S25: =IF($B182="","",$AH182) -> 163 | T25: =IF($B182="","",$AI182) -> 0.011821017 | U25: =IF($B182="","",$AJ182) -> 4.386 | V25: =IF($B182="","",$AK182) -> 0 | W25: =IF($B182="","",$AL182) -> 167.386
A26: 21 | F26: =IF(OR($C26="",$D26=""),"",IFERROR(LOOKUP(2,1/(($C$6:$C$155=$C26)*($B$6:$B$155="Đã chốt")*($E$6:$E$155<$D26)*($G$6:$G$155<>"")),$G$6:$G$155),"")) | H26: =IF(OR($C26="",$D26="",$E26=""),"",SUMIFS(DATA_GOC!$H:$H,DATA_GOC!$A:$A,"NHAP",DATA_GOC!$E:$E,$C26,DATA_GOC!$B:$B,">="&$D26,DATA_GOC!$B:$B,"<="&$E26)) | I26: =IF(OR($C26="",$D26="",$E26=""),"",SUMIFS(DATA_GOC!$H:$H,DATA_GOC!$A:$A,"BOM",DATA_GOC!$E:$E,$C26,DATA_GOC!$F:$F,"Xuất nội bộ từ téc",DATA_GOC!$B:$B,">="&$D26,DATA_GOC!$B:$B,"<="&$E26)) | J26: =IF($I26="","",N($F26)+N($H26)-N($I26)) | K26: =IF($J26="","",MAX(0,N($J26)-N($G26))) | L26: =IF($J26="","",MAX(0,N($G26)-N($J26))) | M26: =IF($E26="","",MONTH($E26)) | N26: =IF($E26="","",YEAR($E26)) | Q26: =IF($B183="","",$A183) -> 16 | R26: =IF($B183="","",$B183) -> 28C02986 | S26: =IF($B183="","",$AH183) -> 930 | T26: =IF($B183="","",$AI183) -> 0.067445065 | U26: =IF($B183="","",$AJ183) -> 25.022 | V26: =IF($B183="","",$AK183) -> 0 | W26: =IF($B183="","",$AL183) -> 955.022
A27: 22 | F27: =IF(OR($C27="",$D27=""),"",IFERROR(LOOKUP(2,1/(($C$6:$C$155=$C27)*($B$6:$B$155="Đã chốt")*($E$6:$E$155<$D27)*($G$6:$G$155<>"")),$G$6:$G$155),"")) | H27: =IF(OR($C27="",$D27="",$E27=""),"",SUMIFS(DATA_GOC!$H:$H,DATA_GOC!$A:$A,"NHAP",DATA_GOC!$E:$E,$C27,DATA_GOC!$B:$B,">="&$D27,DATA_GOC!$B:$B,"<="&$E27)) | I27: =IF(OR($C27="",$D27="",$E27=""),"",SUMIFS(DATA_GOC!$H:$H,DATA_GOC!$A:$A,"BOM",DATA_GOC!$E:$E,$C27,DATA_GOC!$F:$F,"Xuất nội bộ từ téc",DATA_GOC!$B:$B,">="&$D27,DATA_GOC!$B:$B,"<="&$E27)) | J27: =IF($I27="","",N($F27)+N($H27)-N($I27)) | K27: =IF($J27="","",MAX(0,N($J27)-N($G27))) | L27: =IF($J27="","",MAX(0,N($G27)-N($J27))) | M27: =IF($E27="","",MONTH($E27)) | N27: =IF($E27="","",YEAR($E27)) | Q27: =IF($B184="","",$A184) -> 17 | R27: =IF($B184="","",$B184) -> 28C03261 | S27: =IF($B184="","",$AH184) -> 220 | T27: =IF($B184="","",$AI184) -> 0.015954747 | U27: =IF($B184="","",$AJ184) -> 5.919 | V27: =IF($B184="","",$AK184) -> 0 | W27: =IF($B184="","",$AL184) -> 225.919
A28: 23 | F28: =IF(OR($C28="",$D28=""),"",IFERROR(LOOKUP(2,1/(($C$6:$C$155=$C28)*($B$6:$B$155="Đã chốt")*($E$6:$E$155<$D28)*($G$6:$G$155<>"")),$G$6:$G$155),"")) | H28: =IF(OR($C28="",$D28="",$E28=""),"",SUMIFS(DATA_GOC!$H:$H,DATA_GOC!$A:$A,"NHAP",DATA_GOC!$E:$E,$C28,DATA_GOC!$B:$B,">="&$D28,DATA_GOC!$B:$B,"<="&$E28)) | I28: =IF(OR($C28="",$D28="",$E28=""),"",SUMIFS(DATA_GOC!$H:$H,DATA_GOC!$A:$A,"BOM",DATA_GOC!$E:$E,$C28,DATA_GOC!$F:$F,"Xuất nội bộ từ téc",DATA_GOC!$B:$B,">="&$D28,DATA_GOC!$B:$B,"<="&$E28)) | J28: =IF($I28="","",N($F28)+N($H28)-N($I28)) | K28: =IF($J28="","",MAX(0,N($J28)-N($G28))) | L28: =IF($J28="","",MAX(0,N($G28)-N($J28))) | M28: =IF($E28="","",MONTH($E28)) | N28: =IF($E28="","",YEAR($E28)) | Q28: =IF($B185="","",$A185) -> 18 | R28: =IF($B185="","",$B185) -> 28C03323 | S28: =IF($B185="","",$AH185) -> 222 | T28: =IF($B185="","",$AI185) -> 0.01609979 | U28: =IF($B185="","",$AJ185) -> 5.973 | V28: =IF($B185="","",$AK185) -> 0 | W28: =IF($B185="","",$AL185) -> 227.973
A29: 24 | F29: =IF(OR($C29="",$D29=""),"",IFERROR(LOOKUP(2,1/(($C$6:$C$155=$C29)*($B$6:$B$155="Đã chốt")*($E$6:$E$155<$D29)*($G$6:$G$155<>"")),$G$6:$G$155),"")) | H29: =IF(OR($C29="",$D29="",$E29=""),"",SUMIFS(DATA_GOC!$H:$H,DATA_GOC!$A:$A,"NHAP",DATA_GOC!$E:$E,$C29,DATA_GOC!$B:$B,">="&$D29,DATA_GOC!$B:$B,"<="&$E29)) | I29: =IF(OR($C29="",$D29="",$E29=""),"",SUMIFS(DATA_GOC!$H:$H,DATA_GOC!$A:$A,"BOM",DATA_GOC!$E:$E,$C29,DATA_GOC!$F:$F,"Xuất nội bộ từ téc",DATA_GOC!$B:$B,">="&$D29,DATA_GOC!$B:$B,"<="&$E29)) | J29: =IF($I29="","",N($F29)+N($H29)-N($I29)) | K29: =IF($J29="","",MAX(0,N($J29)-N($G29))) | L29: =IF($J29="","",MAX(0,N($G29)-N($J29))) | M29: =IF($E29="","",MONTH($E29)) | N29: =IF($E29="","",YEAR($E29)) | Q29: =IF($B186="","",$A186) -> 19 | R29: =IF($B186="","",$B186) -> 28C03385 | S29: =IF($B186="","",$AH186) -> 300 | T29: =IF($B186="","",$AI186) -> 0.021756473 | U29: =IF($B186="","",$AJ186) -> 8.072 | V29: =IF($B186="","",$AK186) -> 0 | W29: =IF($B186="","",$AL186) -> 308.072
A30: 25 | F30: =IF(OR($C30="",$D30=""),"",IFERROR(LOOKUP(2,1/(($C$6:$C$155=$C30)*($B$6:$B$155="Đã chốt")*($E$6:$E$155<$D30)*($G$6:$G$155<>"")),$G$6:$G$155),"")) | H30: =IF(OR($C30="",$D30="",$E30=""),"",SUMIFS(DATA_GOC!$H:$H,DATA_GOC!$A:$A,"NHAP",DATA_GOC!$E:$E,$C30,DATA_GOC!$B:$B,">="&$D30,DATA_GOC!$B:$B,"<="&$E30)) | I30: =IF(OR($C30="",$D30="",$E30=""),"",SUMIFS(DATA_GOC!$H:$H,DATA_GOC!$A:$A,"BOM",DATA_GOC!$E:$E,$C30,DATA_GOC!$F:$F,"Xuất nội bộ từ téc",DATA_GOC!$B:$B,">="&$D30,DATA_GOC!$B:$B,"<="&$E30)) | J30: =IF($I30="","",N($F30)+N($H30)-N($I30)) | K30: =IF($J30="","",MAX(0,N($J30)-N($G30))) | L30: =IF($J30="","",MAX(0,N($G30)-N($J30))) | M30: =IF($E30="","",MONTH($E30)) | N30: =IF($E30="","",YEAR($E30)) | Q30: =IF($B187="","",$A187) -> 20 | R30: =IF($B187="","",$B187) -> 28C03652 | S30: =IF($B187="","",$AH187) -> 0 | T30: =IF($B187="","",$AI187) -> 0 | U30: =IF($B187="","",$AJ187) -> 0 | V30: =IF($B187="","",$AK187) -> 0 | W30: =IF($B187="","",$AL187) -> 0
A31: 26 | F31: =IF(OR($C31="",$D31=""),"",IFERROR(LOOKUP(2,1/(($C$6:$C$155=$C31)*($B$6:$B$155="Đã chốt")*($E$6:$E$155<$D31)*($G$6:$G$155<>"")),$G$6:$G$155),"")) | H31: =IF(OR($C31="",$D31="",$E31=""),"",SUMIFS(DATA_GOC!$H:$H,DATA_GOC!$A:$A,"NHAP",DATA_GOC!$E:$E,$C31,DATA_GOC!$B:$B,">="&$D31,DATA_GOC!$B:$B,"<="&$E31)) | I31: =IF(OR($C31="",$D31="",$E31=""),"",SUMIFS(DATA_GOC!$H:$H,DATA_GOC!$A:$A,"BOM",DATA_GOC!$E:$E,$C31,DATA_GOC!$F:$F,"Xuất nội bộ từ téc",DATA_GOC!$B:$B,">="&$D31,DATA_GOC!$B:$B,"<="&$E31)) | J31: =IF($I31="","",N($F31)+N($H31)-N($I31)) | K31: =IF($J31="","",MAX(0,N($J31)-N($G31))) | L31: =IF($J31="","",MAX(0,N($G31)-N($J31))) | M31: =IF($E31="","",MONTH($E31)) | N31: =IF($E31="","",YEAR($E31)) | Q31: =IF($B188="","",$A188) -> 21 | R31: =IF($B188="","",$B188) -> 28C03695 | S31: =IF($B188="","",$AH188) -> 211 | T31: =IF($B188="","",$AI188) -> 0.015302052 | U31: =IF($B188="","",$AJ188) -> 5.677 | V31: =IF($B188="","",$AK188) -> 0 | W31: =IF($B188="","",$AL188) -> 216.677
A32: 27 | F32: =IF(OR($C32="",$D32=""),"",IFERROR(LOOKUP(2,1/(($C$6:$C$155=$C32)*($B$6:$B$155="Đã chốt")*($E$6:$E$155<$D32)*($G$6:$G$155<>"")),$G$6:$G$155),"")) | H32: =IF(OR($C32="",$D32="",$E32=""),"",SUMIFS(DATA_GOC!$H:$H,DATA_GOC!$A:$A,"NHAP",DATA_GOC!$E:$E,$C32,DATA_GOC!$B:$B,">="&$D32,DATA_GOC!$B:$B,"<="&$E32)) | I32: =IF(OR($C32="",$D32="",$E32=""),"",SUMIFS(DATA_GOC!$H:$H,DATA_GOC!$A:$A,"BOM",DATA_GOC!$E:$E,$C32,DATA_GOC!$F:$F,"Xuất nội bộ từ téc",DATA_GOC!$B:$B,">="&$D32,DATA_GOC!$B:$B,"<="&$E32)) | J32: =IF($I32="","",N($F32)+N($H32)-N($I32)) | K32: =IF($J32="","",MAX(0,N($J32)-N($G32))) | L32: =IF($J32="","",MAX(0,N($G32)-N($J32))) | M32: =IF($E32="","",MONTH($E32)) | N32: =IF($E32="","",YEAR($E32)) | Q32: =IF($B189="","",$A189) -> 22 | R32: =IF($B189="","",$B189) -> 28C03927 | S32: =IF($B189="","",$AH189) -> 275 | T32: =IF($B189="","",$AI189) -> 0.019943433 | U32: =IF($B189="","",$AJ189) -> 7.399 | V32: =IF($B189="","",$AK189) -> 0 | W32: =IF($B189="","",$AL189) -> 282.399
A33: 28 | F33: =IF(OR($C33="",$D33=""),"",IFERROR(LOOKUP(2,1/(($C$6:$C$155=$C33)*($B$6:$B$155="Đã chốt")*($E$6:$E$155<$D33)*($G$6:$G$155<>"")),$G$6:$G$155),"")) | H33: =IF(OR($C33="",$D33="",$E33=""),"",SUMIFS(DATA_GOC!$H:$H,DATA_GOC!$A:$A,"NHAP",DATA_GOC!$E:$E,$C33,DATA_GOC!$B:$B,">="&$D33,DATA_GOC!$B:$B,"<="&$E33)) | I33: =IF(OR($C33="",$D33="",$E33=""),"",SUMIFS(DATA_GOC!$H:$H,DATA_GOC!$A:$A,"BOM",DATA_GOC!$E:$E,$C33,DATA_GOC!$F:$F,"Xuất nội bộ từ téc",DATA_GOC!$B:$B,">="&$D33,DATA_GOC!$B:$B,"<="&$E33)) | J33: =IF($I33="","",N($F33)+N($H33)-N($I33)) | K33: =IF($J33="","",MAX(0,N($J33)-N($G33))) | L33: =IF($J33="","",MAX(0,N($G33)-N($J33))) | M33: =IF($E33="","",MONTH($E33)) | N33: =IF($E33="","",YEAR($E33)) | Q33: =IF($B190="","",$A190) -> 23 | R33: =IF($B190="","",$B190) -> 28C04509 | S33: =IF($B190="","",$AH190) -> 46 | T33: =IF($B190="","",$AI190) -> 0.0033359925 | U33: =IF($B190="","",$AJ190) -> 1.238 | V33: =IF($B190="","",$AK190) -> 0 | W33: =IF($B190="","",$AL190) -> 47.238
A34: 29 | F34: =IF(OR($C34="",$D34=""),"",IFERROR(LOOKUP(2,1/(($C$6:$C$155=$C34)*($B$6:$B$155="Đã chốt")*($E$6:$E$155<$D34)*($G$6:$G$155<>"")),$G$6:$G$155),"")) | H34: =IF(OR($C34="",$D34="",$E34=""),"",SUMIFS(DATA_GOC!$H:$H,DATA_GOC!$A:$A,"NHAP",DATA_GOC!$E:$E,$C34,DATA_GOC!$B:$B,">="&$D34,DATA_GOC!$B:$B,"<="&$E34)) | I34: =IF(OR($C34="",$D34="",$E34=""),"",SUMIFS(DATA_GOC!$H:$H,DATA_GOC!$A:$A,"BOM",DATA_GOC!$E:$E,$C34,DATA_GOC!$F:$F,"Xuất nội bộ từ téc",DATA_GOC!$B:$B,">="&$D34,DATA_GOC!$B:$B,"<="&$E34)) | J34: =IF($I34="","",N($F34)+N($H34)-N($I34)) | K34: =IF($J34="","",MAX(0,N($J34)-N($G34))) | L34: =IF($J34="","",MAX(0,N($G34)-N($J34))) | M34: =IF($E34="","",MONTH($E34)) | N34: =IF($E34="","",YEAR($E34)) | Q34: =IF($B191="","",$A191) -> 24 | R34: =IF($B191="","",$B191) -> 28C04536 | S34: =IF($B191="","",$AH191) -> 0 | T34: =IF($B191="","",$AI191) -> 0 | U34: =IF($B191="","",$AJ191) -> 0 | V34: =IF($B191="","",$AK191) -> 0 | W34: =IF($B191="","",$AL191) -> 0
A35: 30 | F35: =IF(OR($C35="",$D35=""),"",IFERROR(LOOKUP(2,1/(($C$6:$C$155=$C35)*($B$6:$B$155="Đã chốt")*($E$6:$E$155<$D35)*($G$6:$G$155<>"")),$G$6:$G$155),"")) | H35: =IF(OR($C35="",$D35="",$E35=""),"",SUMIFS(DATA_GOC!$H:$H,DATA_GOC!$A:$A,"NHAP",DATA_GOC!$E:$E,$C35,DATA_GOC!$B:$B,">="&$D35,DATA_GOC!$B:$B,"<="&$E35)) | I35: =IF(OR($C35="",$D35="",$E35=""),"",SUMIFS(DATA_GOC!$H:$H,DATA_GOC!$A:$A,"BOM",DATA_GOC!$E:$E,$C35,DATA_GOC!$F:$F,"Xuất nội bộ từ téc",DATA_GOC!$B:$B,">="&$D35,DATA_GOC!$B:$B,"<="&$E35)) | J35: =IF($I35="","",N($F35)+N($H35)-N($I35)) | K35: =IF($J35="","",MAX(0,N($J35)-N($G35))) | L35: =IF($J35="","",MAX(0,N($G35)-N($J35))) | M35: =IF($E35="","",MONTH($E35)) | N35: =IF($E35="","",YEAR($E35)) | Q35: =IF($B192="","",$A192) -> 25 | R35: =IF($B192="","",$B192) -> 28C04576 | S35: =IF($B192="","",$AH192) -> 240 | T35: =IF($B192="","",$AI192) -> 0.017405178 | U35: =IF($B192="","",$AJ192) -> 6.457 | V35: =IF($B192="","",$AK192) -> 0 | W35: =IF($B192="","",$AL192) -> 246.457
... A70: 65 | F70: =IF(OR($C70="",$D70=""),"",IFERROR(LOOKUP(2,1/(($C$6:$C$155=$C70)*($B$6:$B$155="Đã chốt")*($E$6:$E$155<$D70)*($G$6:$G$155<>"")),$G$6:$G$155),"")) | H70: =IF(OR($C70="",$D70="",$E70=""),"",SUMIFS(DATA_GOC!$H:$H,DATA_GOC!$A:$A,"NHAP",DATA_GOC!$E:$E,$C70,DATA_GOC!$B:$B,">="&$D70,DATA_GOC!$B:$B,"<="&$E70)) | I70: =IF(OR($C70="",$D70="",$E70=""),"",SUMIFS(DATA_GOC!$H:$H,DATA_GOC!$A:$A,"BOM",DATA_GOC!$E:$E,$C70,DATA_GOC!$F:$F,"Xuất nội bộ từ téc",DATA_GOC!$B:$B,">="&$D70,DATA_GOC!$B:$B,"<="&$E70)) | J70: =IF($I70="","",N($F70)+N($H70)-N($I70)) | K70: =IF($J70="","",MAX(0,N($J70)-N($G70))) | L70: =IF($J70="","",MAX(0,N($G70)-N($J70))) | M70: =IF($E70="","",MONTH($E70)) | N70: =IF($E70="","",YEAR($E70)) | Q70: =IF($B227="","",$A227) -> 60 | R70: =IF($B227="","",$B227) -> Xe ben mới | S70: =IF($B227="","",$AH227) -> 0 | T70: =IF($B227="","",$AI227) -> 0 | U70: =IF($B227="","",$AJ227) -> 0 | V70: =IF($B227="","",$AK227) -> 0 | W70: =IF($B227="","",$AL227) -> 0
A71: 66 | F71: =IF(OR($C71="",$D71=""),"",IFERROR(LOOKUP(2,1/(($C$6:$C$155=$C71)*($B$6:$B$155="Đã chốt")*($E$6:$E$155<$D71)*($G$6:$G$155<>"")),$G$6:$G$155),"")) | H71: =IF(OR($C71="",$D71="",$E71=""),"",SUMIFS(DATA_GOC!$H:$H,DATA_GOC!$A:$A,"NHAP",DATA_GOC!$E:$E,$C71,DATA_GOC!$B:$B,">="&$D71,DATA_GOC!$B:$B,"<="&$E71)) | I71: =IF(OR($C71="",$D71="",$E71=""),"",SUMIFS(DATA_GOC!$H:$H,DATA_GOC!$A:$A,"BOM",DATA_GOC!$E:$E,$C71,DATA_GOC!$F:$F,"Xuất nội bộ từ téc",DATA_GOC!$B:$B,">="&$D71,DATA_GOC!$B:$B,"<="&$E71)) | J71: =IF($I71="","",N($F71)+N($H71)-N($I71)) | K71: =IF($J71="","",MAX(0,N($J71)-N($G71))) | L71: =IF($J71="","",MAX(0,N($G71)-N($J71))) | M71: =IF($E71="","",MONTH($E71)) | N71: =IF($E71="","",YEAR($E71))
